Workbook
Name BingSearchKey: Config!$B$4
Name SegmentId: Dashboard!$E$2
Name SerpApiKey: Config!$B$5

Sheet Brand_Kit
A1: Certify Intel v1 — Excel-Only (Brand Kit)
A3: PLACEHOLDER BRANDING: Replace with official Certify Health assets (logo + hex colors).
A5: Logo (placeholder):
A12: Colors
A13: Name | B13: Hex | D13: Swatch
A14: Primary | B14: #0B2E4A
A15: Secondary | B15: #1E9FB3
A16: Accent | B16: #F2A900
A17: Background | B17: #F5F7FA
A18: Border | B18: #D0D7DE
A20: Typography
A21: Header Font | B21: Aptos Display
A22: Body Font | B22: Aptos

Sheet Config
A1: Config (Inputs in BLUE)
A3: API Keys (optional; for autonomous competitor discovery via web search APIs)
A4: Bing Search API Key | B4: ENTER_KEY
A5: SerpAPI Key | B5: ENTER_KEY
A6: Max Competitors to Import | B6: 50
A8: Refresh Settings
A9: Evidence freshness threshold (days) | B9: 30
A10: Minimum allowed known-coverage (fail closed below) | B10: 0.6
A12: Scoring Weights (editable)
A13: Weight | B13: Value
A14: Threat_FeatureOverlap | B14: 0.35
A15: Threat_PricingAggressive | B15: 0.25
A16: Threat_FundingVelocity | B16: 0.2
A17: Threat_SegmentFit | B17: 0.2
A18: Opp_FeatureGap | B18: 0.5
A19: Opp_WeakSegmentFit | B19: 0.25
A20: Opp_LowCoverage | B20: 0.25

Sheet Sources_Allowlist
A1: Sources Allowlist (Fail-Closed)
A3: Only allowlisted domains/paths can be ingested. Non-allowlisted URLs must be BLOCKED and reviewed.
A4: source_key | B4: tier | C4: domain | D4: allow_path_prefix | E4: deny_path_prefix | F4: enabled | G4: license_notes | H4: owner
A5: DEMO | B5: TIER1 | C5: file | D5: / | F5: TRUE | G5: Local demo evidence (offline) | H5: system
A6: SEC_EDGAR | B6: TIER1 | C6: www.sec.gov | D6: /Archives | E6: /cgi-bin | F6: FALSE | G6: Public filings; respect ToS/rate limits | H6: system
A7: Company_PR | B7: TIER2 | F7: FALSE | G7: Per-entity allowlist required | H7: user
A8: G2 | B8: SIGNAL | C8: www.g2.com | D8: /products | E8: / | F8: FALSE | G8: Requires license / ToS review | H8: user
A9: Capterra | B9: SIGNAL | C9: www.capterra.com | D9: / | E9: / | F9: FALSE | G9: Requires license / ToS review | H9: user

Sheet Segment_Rules
A1: Middle Market Segmentation Rules (Always Applied)
A3: Edit thresholds in BLUE. All metrics and dashboards must filter to this segment.
A4: segment_id | B4: segment_name | C4: revenue_min_usd | D4: revenue_max_usd | E4: practice_size_min | F4: practice_size_max | G4: region_includes | H4: notes
A5: SEG_MM | B5: Middle Market | C5: 5000000 | D5: 200000000 | E5: 5 | F5: 200 | G5: US (all) | H5: Placeholder thresholds; replace with Certify definition

Sheet Field_Dictionary
A1: Field Dictionary (Claim Keys + Quality Gates)
A3: Fail-closed: missing/ambiguous evidence must output UNKNOWN and create review tasks.
A4: field_key | B4: category | C4: value_type | D4: units | E4: min_confidence | F4: requires_tier1 | G4: promotion_rule | H4: example_source | I4: notes
A5: pricing_acv_mid_market | B5: Pricing | C5: number | D5: USD/year | E5: 0.8 | F5: TRUE | G5: PROMOTE_IF>=MINCONF_AND_TIER | H5: pricing page | I5: Explicit annual price or ACV
A6: arr_estimate | B6: Financial | C6: number | D6: USD/year | E6: 0.85 | F6: TRUE | G6: PROMOTE_IF_TIER1_ONLY | H6: 10-K/press | I6: Only explicit ARR mention
A7: contract_terms | B7: Pricing | C7: text | E7: 0.7 | F7: FALSE | G7: PROMOTE_IF>=MINCONF | H7: pricing/terms | I7: Explicit contract duration/cancellation
A8: features | B8: Product | C8: text | E8: 0.65 | F8: FALSE | G8: PROMOTE_IF>=MINCONF | H8: product page | I8: Semicolon-separated feature tags
A9: funding_round | B9: Funding | C9: text | E9: 0.8 | F9: TRUE | G9: PROMOTE_IF_TIER1_ONLY | H9: filings/press | I9: Explicit round amount and date
A10: geo_coverage | B10: Market | C10: text | E10: 0.7 | F10: FALSE | G10: PROMOTE_IF>=MINCONF | H10: about page | I10: Regions served
A11: practice_size_target | B11: Market | C11: text | E11: 0.7 | F11: FALSE | G11: PROMOTE_IF>=MINCONF | H11: case studies | I11: Explicit ICP statements

Sheet Feature_Taxonomy
A1: Feature Taxonomy (canonical features + synonyms)
A4: feature_id | B4: feature_name | C4: category | D4: synonyms_csv | E4: notes
A5: F001 | B5: Eligibility Verification | C5: Revenue Cycle | D5: eligibility check;insurance eligibility
A6: F002 | B6: Prior Authorization | C6: Revenue Cycle | D6: prior auth;pre-authorization
A7: F003 | B7: Patient Payments | C7: Billing | D7: payment portal;online payments
A8: F004 | B8: Scheduling | C8: Front Office | D8: appointment scheduling;calendar

Sheet Input
A1: Input (Normalized; Evidence-Led)
A2: Green = imported/linked; Blue = editable inputs; Yellow/Red = review required.
A4: Entities
A6: entity_id | B6: canonical_name | C6: domain | D6: vertical | E6: region | F6: segment_id | G6: discovered_via | H6: discovered_at | I6: status | J6: hq_city | K6: hq_state | L6: notes
A7: E001 | B7: AcmeRival | C7: acmerival.com | D7: Provider Credentialing | E7: US | F7: SEG_MM | G7: DEMO | H7: 2026-01-12 | I7: ACTIVE | J7: New York | K7: NY | L7: DEMO ROW
A8: E002 | B8: EnrollPro | C8: enrollpro.io | D8: Provider Enrollment | E8: US | F8: SEG_MM | G8: DEMO | H8: 2026-01-12 | I8: ACTIVE | J8: Austin | K8: TX | L8: DEMO ROW
A9: E003 | B9: ComplianceFlow | C9: complianceflow.health | D9: Compliance Automation | E9: US | F9: SEG_MM | G9: DEMO | H9: 2026-01-12 | I9: ACTIVE | J9: Chicago | K9: IL | L9: DEMO ROW
A10: E004 | B10: CredentiSure | C10: credentisure.com | D10: Credentialing | E10: US | F10: SEG_MM | G10: DEMO | H10: 2026-01-12 | I10: ACTIVE | J10: Boston | K10: MA | L10: DEMO ROW
A11: E005 | B11: PracticeOps | C11: practiceops.com | D11: Practice Ops Suite | E11: US | F11: SEG_MM | G11: DEMO | H11: 2026-01-12 | I11: ACTIVE | J11: Miami | K11: FL | L11: DEMO ROW
A12: E006 | B12: MidMarketMedTech | C12: mmmedtech.com | D12: Healthcare IT | E12: US | F12: SEG_MM | G12: DEMO | H12: 2026-01-12 | I12: ACTIVE | J12: Seattle | K12: WA | L12: DEMO ROW
A15: Evidence (Claims must link here)
A17: evidence_id | B17: entity_id | C17: source_key | D17: tier | E17: url | F17: fetched_at | G17: snippet | H17: content_hash | I17: text_hash | J17: domain_calc | K17: allowlist_ok
A18: EV001 | B18: E001 | C18: DEMO | D18: TIER1 | E18: file://docs/demo_sources/E001_pricing.html | F18: 2026-01-12 | G18: DEMO evidence placeholder. Replace with allowlisted URL + snippet. | H18: 0217e879a9ae84b4 | I18: 46aae5c96408e7ec | J18: =IF(LEFT(#REF!,7)="file://","file",LOWER(_xludf.TEXTBEFORE(_xludf.TEXTAFTER(#REF!,"//"),"/"))) -> #REF!
A19: EV002 | B19: E002 | C19: DEMO | D19: TIER1 | E19: file://docs/demo_sources/E002_pricing.html | F19: 2026-01-12 | G19: DEMO evidence placeholder. Replace with allowlisted URL + snippet. | H19: 3deb1e85e3854868 | I19: 46aae5c96408e7ec | J19: =IF(LEFT(#REF!,7)="file://","file",LOWER(_xludf.TEXTBEFORE(_xludf.TEXTAFTER(#REF!,"//"),"/"))) -> #REF!
A20: EV003 | B20: E003 | C20: DEMO | D20: TIER1 | E20: file://docs/demo_sources/E003_pricing.html | F20: 2026-01-12 | G20: DEMO evidence placeholder. Replace with allowlisted URL + snippet. | H20: d42285f8d1a9736f | I20: 46aae5c96408e7ec | J20: =IF(LEFT(#REF!,7)="file://","file",LOWER(_xludf.TEXTBEFORE(_xludf.TEXTAFTER(#REF!,"//"),"/"))) -> #REF!
A21: EV004 | B21: E004 | C21: DEMO | D21: TIER1 | E21: file://docs/demo_sources/E004_pricing.html | F21: 2026-01-12 | G21: DEMO evidence placeholder. Replace with allowlisted URL + snippet. | H21: b1e3c58050111249 | I21: 46aae5c96408e7ec | J21: =IF(LEFT(#REF!,7)="file://","file",LOWER(_xludf.TEXTBEFORE(_xludf.TEXTAFTER(#REF!,"//"),"/"))) -> #REF!
A22: EV005 | B22: E001 | C22: DEMO | D22: SIGNAL | E22: file://docs/demo_sources/E001_pr.html | F22: 2026-01-12 | G22: DEMO PR mention (signal only). | H22: 0510eddd78110203 | I22: 41bfa2f2111d7821 | J22: =IF(LEFT(#REF!,7)="file://","file",LOWER(_xludf.TEXTBEFORE(_xludf.TEXTAFTER(#REF!,"//"),"/"))) -> #REF!
A25: Claim Candidates (Fail-Closed; UNKNOWN → Review)
A27: candidate_id | B27: entity_id | C27: segment_id | D27: field_key | E27: value_text | F27: value_num | G27: units | H27: confidence | I27: evidence_id | J27: span_start | K27: span_end | L27: tier | M27: status_final | N27: status_manual | O27: status_auto | P27: auto_reason | Q27: reviewer_notes
A28: C001 | B28: E001 | C28: SEG_MM | D28: pricing_acv_mid_market | F28: 12000 | G28: USD/year | H28: 0.9 | I28: EV001 | J28: 0 | K28: 200 | L28: TIER1 | M28: =_xludf.LET(man,#REF!,auto,#REF!,IF(man="REJECTED","REJECTED",IF(man="IN_REVIEW","IN_REVIEW",IF(man="PROMOTED",IF(auto="PROMOTABLE","PROMOTED","REVIEW_REQUIRED"),IF(auto="PROMOTABLE","PROMOTED","REVIEW_REQUIRED"))))) -> #NAME? | N28: PROMOTED | O28: =_xludf.LET(minc,IFERROR(_xludf.XLOOKUP(#REF!,tblFieldDictionary[field_key],tblFieldDictionary[min_confidence]),1),REQ1,IFERROR(_xludf.XLOOKUP(#REF!,tblFieldDictionary[field_key],tblFieldDictionary[requires_tier1]),"FALSE"),hasEvid,ISNUMBER(MATCH(#REF!,tblEvidence[evidence_id],0)),hasVal,OR(AND(#REF!<>"",#REF!<>"UNKNOWN"),#REF!<>""),confOK,#REF!>=minc,tierOK,IF(REQ1="TRUE",#REF!="TIER1",TRUE),IF(NOT(hasEvid),"REVIEW_REQUIRED",IF(NOT(hasVal),"REVIEW_REQUIRED",IF(NOT(confOK),"REVIEW_REQUIRED",IF(NOT(tierOK),"REVIEW_REQUIRED","PROMOTABLE"))))) -> #NAME? | P28: =_xludf.LET(minc,IFERROR(_xludf.XLOOKUP(#REF!,tblFieldDictionary[field_key],tblFieldDictionary[min_confidence]),1),REQ1,IFERROR(_xludf.XLOOKUP(#REF!,tblFieldDictionary[field_key],tblFieldDictionary[requires_tier1]),"FALSE"),hasEvid,ISNUMBER(MATCH(#REF!,tblEvidence[evidence_id],0)),hasVal,OR(AND(#REF!<>"",#REF!<>"UNKNOWN"),#REF!<>""),confOK,#REF!>=minc,tierOK,IF(REQ1="TRUE",#REF!="TIER1",TRUE),IF(NOT(hasEvid),"MISSING_EVIDENCE",IF(NOT(hasVal),"MISSING_VALUE",IF(NOT(confOK),"LOW_CONFIDENCE",IF(NOT(tierOK),"TIER1_REQUIRED","OK"))))) -> #NAME?
A29: C002 | B29: E001 | C29: SEG_MM | D29: contract_terms | E29: Annual contract, cancel with 30 days notice | H29: 0.75 | I29: EV001 | J29: 201 | K29: 320 | L29: TIER1 | M29: =_xludf.LET(man,#REF!,auto,#REF!,IF(man="REJECTED","REJECTED",IF(man="IN_REVIEW","IN_REVIEW",IF(man="PROMOTED",IF(auto="PROMOTABLE","PROMOTED","REVIEW_REQUIRED"),IF(auto="PROMOTABLE","PROMOTED","REVIEW_REQUIRED"))))) -> #NAME? | N29: PROMOTED | O29: =_xludf.LET(minc,IFERROR(_xludf.XLOOKUP(#REF!,tblFieldDictionary[field_key],tblFieldDictionary[min_confidence]),1),REQ1,IFERROR(_xludf.XLOOKUP(#REF!,tblFieldDictionary[field_key],tblFieldDictionary[requires_tier1]),"FALSE"),hasEvid,ISNUMBER(MATCH(#REF!,tblEvidence[evidence_id],0)),hasVal,OR(AND(#REF!<>"",#REF!<>"UNKNOWN"),#REF!<>""),confOK,#REF!>=minc,tierOK,IF(REQ1="TRUE",#REF!="TIER1",TRUE),IF(NOT(hasEvid),"REVIEW_REQUIRED",IF(NOT(hasVal),"REVIEW_REQUIRED",IF(NOT(confOK),"REVIEW_REQUIRED",IF(NOT(tierOK),"REVIEW_REQUIRED","PROMOTABLE"))))) -> #NAME? | P29: =_xludf.LET(minc,IFERROR(_xludf.XLOOKUP(#REF!,tblFieldDictionary[field_key],tblFieldDictionary[min_confidence]),1),REQ1,IFERROR(_xludf.XLOOKUP(#REF!,tblFieldDictionary[field_key],tblFieldDictionary[requires_tier1]),"FALSE"),hasEvid,ISNUMBER(MATCH(#REF!,tblEvidence[evidence_id],0)),hasVal,OR(AND(#REF!<>"",#REF!<>"UNKNOWN"),#REF!<>""),confOK,#REF!>=minc,tierOK,IF(REQ1="TRUE",#REF!="TIER1",TRUE),IF(NOT(hasEvid),"MISSING_EVIDENCE",IF(NOT(hasVal),"MISSING_VALUE",IF(NOT(confOK),"LOW_CONFIDENCE",IF(NOT(tierOK),"TIER1_REQUIRED","OK"))))) -> #NAME?
A30: C003 | B30: E001 | C30: SEG_MM | D30: features | E30: Credentialing; Enrollment; Payer Roster | H30: 0.7 | I30: EV001 | J30: 321 | K30: 520 | L30: TIER1 | M30: =_xludf.LET(man,#REF!,auto,#REF!,IF(man="REJECTED","REJECTED",IF(man="IN_REVIEW","IN_REVIEW",IF(man="PROMOTED",IF(auto="PROMOTABLE","PROMOTED","REVIEW_REQUIRED"),IF(auto="PROMOTABLE","PROMOTED","REVIEW_REQUIRED"))))) -> #NAME? | N30: PROMOTED | O30: =_xludf.LET(minc,IFERROR(_xludf.XLOOKUP(#REF!,tblFieldDictionary[field_key],tblFieldDictionary[min_confidence]),1),REQ1,IFERROR(_xludf.XLOOKUP(#REF!,tblFieldDictionary[field_key],tblFieldDictionary[requires_tier1]),"FALSE"),hasEvid,ISNUMBER(MATCH(#REF!,tblEvidence[evidence_id],0)),hasVal,OR(AND(#REF!<>"",#REF!<>"UNKNOWN"),#REF!<>""),confOK,#REF!>=minc,tierOK,IF(REQ1="TRUE",#REF!="TIER1",TRUE),IF(NOT(hasEvid),"REVIEW_REQUIRED",IF(NOT(hasVal),"REVIEW_REQUIRED",IF(NOT(confOK),"REVIEW_REQUIRED",IF(NOT(tierOK),"REVIEW_REQUIRED","PROMOTABLE"))))) -> #NAME? | P30: =_xludf.LET(minc,IFERROR(_xludf.XLOOKUP(#REF!,tblFieldDictionary[field_key],tblFieldDictionary[min_confidence]),1),REQ1,IFERROR(_xludf.XLOOKUP(#REF!,tblFieldDictionary[field_key],tblFieldDictionary[requires_tier1]),"FALSE"),hasEvid,ISNUMBER(MATCH(#REF!,tblEvidence[evidence_id],0)),hasVal,OR(AND(#REF!<>"",#REF!<>"UNKNOWN"),#REF!<>""),confOK,#REF!>=minc,tierOK,IF(REQ1="TRUE",#REF!="TIER1",TRUE),IF(NOT(hasEvid),"MISSING_EVIDENCE",IF(NOT(hasVal),"MISSING_VALUE",IF(NOT(confOK),"LOW_CONFIDENCE",IF(NOT(tierOK),"TIER1_REQUIRED","OK"))))) -> #NAME?
A31: C004 | B31: E002 | C31: SEG_MM | D31: pricing_acv_mid_market | E31: UNKNOWN | G31: USD/year | H31: 0.2 | I31: EV002 | J31: 0 | K31: 180 | L31: TIER1 | M31: =_xludf.LET(man,#REF!,auto,#REF!,IF(man="REJECTED","REJECTED",IF(man="IN_REVIEW","IN_REVIEW",IF(man="PROMOTED",IF(auto="PROMOTABLE","PROMOTED","REVIEW_REQUIRED"),IF(auto="PROMOTABLE","PROMOTED","REVIEW_REQUIRED"))))) -> #NAME? | N31: REVIEW_REQUIRED | O31: =_xludf.LET(minc,IFERROR(_xludf.XLOOKUP(#REF!,tblFieldDictionary[field_key],tblFieldDictionary[min_confidence]),1),REQ1,IFERROR(_xludf.XLOOKUP(#REF!,tblFieldDictionary[field_key],tblFieldDictionary[requires_tier1]),"FALSE"),hasEvid,ISNUMBER(MATCH(#REF!,tblEvidence[evidence_id],0)),hasVal,OR(AND(#REF!<>"",#REF!<>"UNKNOWN"),#REF!<>""),confOK,#REF!>=minc,tierOK,IF(REQ1="TRUE",#REF!="TIER1",TRUE),IF(NOT(hasEvid),"REVIEW_REQUIRED",IF(NOT(hasVal),"REVIEW_REQUIRED",IF(NOT(confOK),"REVIEW_REQUIRED",IF(NOT(tierOK),"REVIEW_REQUIRED","PROMOTABLE"))))) -> #NAME? | P31: =_xludf.LET(minc,IFERROR(_xludf.XLOOKUP(#REF!,tblFieldDictionary[field_key],tblFieldDictionary[min_confidence]),1),REQ1,IFERROR(_xludf.XLOOKUP(#REF!,tblFieldDictionary[field_key],tblFieldDictionary[requires_tier1]),"FALSE"),hasEvid,ISNUMBER(MATCH(#REF!,tblEvidence[evidence_id],0)),hasVal,OR(AND(#REF!<>"",#REF!<>"UNKNOWN"),#REF!<>""),confOK,#REF!>=minc,tierOK,IF(REQ1="TRUE",#REF!="TIER1",TRUE),IF(NOT(hasEvid),"MISSING_EVIDENCE",IF(NOT(hasVal),"MISSING_VALUE",IF(NOT(confOK),"LOW_CONFIDENCE",IF(NOT(tierOK),"TIER1_REQUIRED","OK"))))) -> #NAME? | Q31: No explicit ACV on page
A32: C005 | B32: E002 | C32: SEG_MM | D32: features | E32: Enrollment; Automated forms; Integrations | H32: 0.7 | I32: EV002 | J32: 181 | K32: 420 | L32: TIER1 | M32: =_xludf.LET(man,#REF!,auto,#REF!,IF(man="REJECTED","REJECTED",IF(man="IN_REVIEW","IN_REVIEW",IF(man="PROMOTED",IF(auto="PROMOTABLE","PROMOTED","REVIEW_REQUIRED"),IF(auto="PROMOTABLE","PROMOTED","REVIEW_REQUIRED"))))) -> #NAME? | N32: PROMOTED | O32: =_xludf.LET(minc,IFERROR(_xludf.XLOOKUP(#REF!,tblFieldDictionary[field_key],tblFieldDictionary[min_confidence]),1),REQ1,IFERROR(_xludf.XLOOKUP(#REF!,tblFieldDictionary[field_key],tblFieldDictionary[requires_tier1]),"FALSE"),hasEvid,ISNUMBER(MATCH(#REF!,tblEvidence[evidence_id],0)),hasVal,OR(AND(#REF!<>"",#REF!<>"UNKNOWN"),#REF!<>""),confOK,#REF!>=minc,tierOK,IF(REQ1="TRUE",#REF!="TIER1",TRUE),IF(NOT(hasEvid),"REVIEW_REQUIRED",IF(NOT(hasVal),"REVIEW_REQUIRED",IF(NOT(confOK),"REVIEW_REQUIRED",IF(NOT(tierOK),"REVIEW_REQUIRED","PROMOTABLE"))))) -> #NAME? | P32: =_xludf.LET(minc,IFERROR(_xludf.XLOOKUP(#REF!,tblFieldDictionary[field_key],tblFieldDictionary[min_confidence]),1),REQ1,IFERROR(_xludf.XLOOKUP(#REF!,tblFieldDictionary[field_key],tblFieldDictionary[requires_tier1]),"FALSE"),hasEvid,ISNUMBER(MATCH(#REF!,tblEvidence[evidence_id],0)),hasVal,OR(AND(#REF!<>"",#REF!<>"UNKNOWN"),#REF!<>""),confOK,#REF!>=minc,tierOK,IF(REQ1="TRUE",#REF!="TIER1",TRUE),IF(NOT(hasEvid),"MISSING_EVIDENCE",IF(NOT(hasVal),"MISSING_VALUE",IF(NOT(confOK),"LOW_CONFIDENCE",IF(NOT(tierOK),"TIER1_REQUIRED","OK"))))) -> #NAME?
A33: C006 | B33: E003 | C33: SEG_MM | D33: funding_round | E33: UNKNOWN | H33: 0.1 | I33: EV003 | J33: 0 | K33: 250 | L33: SIGNAL | M33: =_xludf.LET(man,#REF!,auto,#REF!,IF(man="REJECTED","REJECTED",IF(man="IN_REVIEW","IN_REVIEW",IF(man="PROMOTED",IF(auto="PROMOTABLE","PROMOTED","REVIEW_REQUIRED"),IF(auto="PROMOTABLE","PROMOTED","REVIEW_REQUIRED"))))) -> #NAME? | N33: REVIEW_REQUIRED | O33: =_xludf.LET(minc,IFERROR(_xludf.XLOOKUP(#REF!,tblFieldDictionary[field_key],tblFieldDictionary[min_confidence]),1),REQ1,IFERROR(_xludf.XLOOKUP(#REF!,tblFieldDictionary[field_key],tblFieldDictionary[requires_tier1]),"FALSE"),hasEvid,ISNUMBER(MATCH(#REF!,tblEvidence[evidence_id],0)),hasVal,OR(AND(#REF!<>"",#REF!<>"UNKNOWN"),#REF!<>""),confOK,#REF!>=minc,tierOK,IF(REQ1="TRUE",#REF!="TIER1",TRUE),IF(NOT(hasEvid),"REVIEW_REQUIRED",IF(NOT(hasVal),"REVIEW_REQUIRED",IF(NOT(confOK),"REVIEW_REQUIRED",IF(NOT(tierOK),"REVIEW_REQUIRED","PROMOTABLE"))))) -> #NAME? | P33: =_xludf.LET(minc,IFERROR(_xludf.XLOOKUP(#REF!,tblFieldDictionary[field_key],tblFieldDictionary[min_confidence]),1),REQ1,IFERROR(_xludf.XLOOKUP(#REF!,tblFieldDictionary[field_key],tblFieldDictionary[requires_tier1]),"FALSE"),hasEvid,ISNUMBER(MATCH(#REF!,tblEvidence[evidence_id],0)),hasVal,OR(AND(#REF!<>"",#REF!<>"UNKNOWN"),#REF!<>""),confOK,#REF!>=minc,tierOK,IF(REQ1="TRUE",#REF!="TIER1",TRUE),IF(NOT(hasEvid),"MISSING_EVIDENCE",IF(NOT(hasVal),"MISSING_VALUE",IF(NOT(confOK),"LOW_CONFIDENCE",IF(NOT(tierOK),"TIER1_REQUIRED","OK"))))) -> #NAME? | Q33: Signal only; needs tier-1 corroboration
A34: C007 | B34: E004 | C34: SEG_MM | D34: pricing_acv_mid_market | F34: 18000 | G34: USD/year | H34: 0.82 | I34: EV004 | J34: 0 | K34: 210 | L34: TIER1 | M34: =_xludf.LET(man,#REF!,auto,#REF!,IF(man="REJECTED","REJECTED",IF(man="IN_REVIEW","IN_REVIEW",IF(man="PROMOTED",IF(auto="PROMOTABLE","PROMOTED","REVIEW_REQUIRED"),IF(auto="PROMOTABLE","PROMOTED","REVIEW_REQUIRED"))))) -> #NAME? | N34: PROMOTED | O34: =_xludf.LET(minc,IFERROR(_xludf.XLOOKUP(#REF!,tblFieldDictionary[field_key],tblFieldDictionary[min_confidence]),1),REQ1,IFERROR(_xludf.XLOOKUP(#REF!,tblFieldDictionary[field_key],tblFieldDictionary[requires_tier1]),"FALSE"),hasEvid,ISNUMBER(MATCH(#REF!,tblEvidence[evidence_id],0)),hasVal,OR(AND(#REF!<>"",#REF!<>"UNKNOWN"),#REF!<>""),confOK,#REF!>=minc,tierOK,IF(REQ1="TRUE",#REF!="TIER1",TRUE),IF(NOT(hasEvid),"REVIEW_REQUIRED",IF(NOT(hasVal),"REVIEW_REQUIRED",IF(NOT(confOK),"REVIEW_REQUIRED",IF(NOT(tierOK),"REVIEW_REQUIRED","PROMOTABLE"))))) -> #NAME? | P34: =_xludf.LET(minc,IFERROR(_xludf.XLOOKUP(#REF!,tblFieldDictionary[field_key],tblFieldDictionary[min_confidence]),1),REQ1,IFERROR(_xludf.XLOOKUP(#REF!,tblFieldDictionary[field_key],tblFieldDictionary[requires_tier1]),"FALSE"),hasEvid,ISNUMBER(MATCH(#REF!,tblEvidence[evidence_id],0)),hasVal,OR(AND(#REF!<>"",#REF!<>"UNKNOWN"),#REF!<>""),confOK,#REF!>=minc,tierOK,IF(REQ1="TRUE",#REF!="TIER1",TRUE),IF(NOT(hasEvid),"MISSING_EVIDENCE",IF(NOT(hasVal),"MISSING_VALUE",IF(NOT(confOK),"LOW_CONFIDENCE",IF(NOT(tierOK),"TIER1_REQUIRED","OK"))))) -> #NAME?
A35: C008 | B35: E004 | C35: SEG_MM | D35: features | E35: Credentialing; Compliance; Analytics | H35: 0.68 | I35: EV004 | J35: 211 | K35: 400 | L35: TIER1 | M35: =_xludf.LET(man,#REF!,auto,#REF!,IF(man="REJECTED","REJECTED",IF(man="IN_REVIEW","IN_REVIEW",IF(man="PROMOTED",IF(auto="PROMOTABLE","PROMOTED","REVIEW_REQUIRED"),IF(auto="PROMOTABLE","PROMOTED","REVIEW_REQUIRED"))))) -> #NAME? | N35: PROMOTED | O35: =_xludf.LET(minc,IFERROR(_xludf.XLOOKUP(#REF!,tblFieldDictionary[field_key],tblFieldDictionary[min_confidence]),1),REQ1,IFERROR(_xludf.XLOOKUP(#REF!,tblFieldDictionary[field_key],tblFieldDictionary[requires_tier1]),"FALSE"),hasEvid,ISNUMBER(MATCH(#REF!,tblEvidence[evidence_id],0)),hasVal,OR(AND(#REF!<>"",#REF!<>"UNKNOWN"),#REF!<>""),confOK,#REF!>=minc,tierOK,IF(REQ1="TRUE",#REF!="TIER1",TRUE),IF(NOT(hasEvid),"REVIEW_REQUIRED",IF(NOT(hasVal),"REVIEW_REQUIRED",IF(NOT(confOK),"REVIEW_REQUIRED",IF(NOT(tierOK),"REVIEW_REQUIRED","PROMOTABLE"))))) -> #NAME? | P35: =_xludf.LET(minc,IFERROR(_xludf.XLOOKUP(#REF!,tblFieldDictionary[field_key],tblFieldDictionary[min_confidence]),1),REQ1,IFERROR(_xludf.XLOOKUP(#REF!,tblFieldDictionary[field_key],tblFieldDictionary[requires_tier1]),"FALSE"),hasEvid,ISNUMBER(MATCH(#REF!,tblEvidence[evidence_id],0)),hasVal,OR(AND(#REF!<>"",#REF!<>"UNKNOWN"),#REF!<>""),confOK,#REF!>=minc,tierOK,IF(REQ1="TRUE",#REF!="TIER1",TRUE),IF(NOT(hasEvid),"MISSING_EVIDENCE",IF(NOT(hasVal),"MISSING_VALUE",IF(NOT(confOK),"LOW_CONFIDENCE",IF(NOT(tierOK),"TIER1_REQUIRED","OK"))))) -> #NAME?
A36: C009 | B36: E005 | C36: SEG_MM | D36: pricing_acv_mid_market | F36: 9000 | G36: USD/year | H36: 0.8 | I36: EV005 | J36: 0 | K36: 200 | L36: SIGNAL | M36: =_xludf.LET(man,#REF!,auto,#REF!,IF(man="REJECTED","REJECTED",IF(man="IN_REVIEW","IN_REVIEW",IF(man="PROMOTED",IF(auto="PROMOTABLE","PROMOTED","REVIEW_REQUIRED"),IF(auto="PROMOTABLE","PROMOTED","REVIEW_REQUIRED"))))) -> #NAME? | N36: REVIEW_REQUIRED | O36: =_xludf.LET(minc,IFERROR(_xludf.XLOOKUP(#REF!,tblFieldDictionary[field_key],tblFieldDictionary[min_confidence]),1),REQ1,IFERROR(_xludf.XLOOKUP(#REF!,tblFieldDictionary[field_key],tblFieldDictionary[requires_tier1]),"FALSE"),hasEvid,ISNUMBER(MATCH(#REF!,tblEvidence[evidence_id],0)),hasVal,OR(AND(#REF!<>"",#REF!<>"UNKNOWN"),#REF!<>""),confOK,#REF!>=minc,tierOK,IF(REQ1="TRUE",#REF!="TIER1",TRUE),IF(NOT(hasEvid),"REVIEW_REQUIRED",IF(NOT(hasVal),"REVIEW_REQUIRED",IF(NOT(confOK),"REVIEW_REQUIRED",IF(NOT(tierOK),"REVIEW_REQUIRED","PROMOTABLE"))))) -> #NAME? | P36: =_xludf.LET(minc,IFERROR(_xludf.XLOOKUP(#REF!,tblFieldDictionary[field_key],tblFieldDictionary[min_confidence]),1),REQ1,IFERROR(_xludf.XLOOKUP(#REF!,tblFieldDictionary[field_key],tblFieldDictionary[requires_tier1]),"FALSE"),hasEvid,ISNUMBER(MATCH(#REF!,tblEvidence[evidence_id],0)),hasVal,OR(AND(#REF!<>"",#REF!<>"UNKNOWN"),#REF!<>""),confOK,#REF!>=minc,tierOK,IF(REQ1="TRUE",#REF!="TIER1",TRUE),IF(NOT(hasEvid),"MISSING_EVIDENCE",IF(NOT(hasVal),"MISSING_VALUE",IF(NOT(confOK),"LOW_CONFIDENCE",IF(NOT(tierOK),"TIER1_REQUIRED","OK"))))) -> #NAME? | Q36: Pricing from signal source; needs tier-1

Sheet Claims_Current
A1: Claims_Current (Normalized Claims; Versioned via Review Workflow)
A2: This sheet is the contract consumed by Metrics and Dashboards. Values must be evidence-backed; missing/uncertain → UNKNOWN.
A4: entity_id | B4: canonical_name | C4: segment_id | D4: field_key | E4: value_text | F4: value_num | G4: units | H4: confidence | I4: evidence_id | J4: evidence_url | K4: tier | L4: status | M4: last_updated | N4: explain
A5: E001 | B5: AcmeRival | C5: SEG_MM | D5: pricing_acv_mid_market | E5: =_xludf.LET(v,IFERROR(LOOKUP(2,1/((tblClaimCandidates[entity_id]=#REF!)*(tblClaimCandidates[field_key]=#REF!)*(tblClaimCandidates[status_final]="PROMOTED")),tblClaimCandidates[value_text]),""),IF(v="","UNKNOWN",v)) -> #NAME? | F5: =_xludf.LET(cnt,COUNTIFS(tblClaimCandidates[entity_id],#REF!,tblClaimCandidates[field_key],#REF!,tblClaimCandidates[status_final],"PROMOTED"),IF(cnt=0,NA(),SUMIFS(tblClaimCandidates[value_num],tblClaimCandidates[entity_id],#REF!,tblClaimCandidates[field_key],#REF!,tblClaimCandidates[status_final],"PROMOTED"))) -> #NAME? | G5: =IFERROR(_xludf.XLOOKUP(#REF!,tblFieldDictionary[field_key],tblFieldDictionary[units]),"") | H5: =_xludf.LET(cnt,COUNTIFS(tblClaimCandidates[entity_id],#REF!,tblClaimCandidates[field_key],#REF!,tblClaimCandidates[status_final],"PROMOTED"),IF(cnt=0,NA(),AVERAGEIFS(tblClaimCandidates[confidence],tblClaimCandidates[entity_id],#REF!,tblClaimCandidates[field_key],#REF!,tblClaimCandidates[status_final],"PROMOTED"))) -> #NAME? | I5: =IFERROR(LOOKUP(2,1/((tblClaimCandidates[entity_id]=#REF!)*(tblClaimCandidates[field_key]=#REF!)*(tblClaimCandidates[status_final]="PROMOTED")),tblClaimCandidates[evidence_id]),"") | J5: =IF(#REF!="","",IFERROR(_xludf.XLOOKUP(#REF!,tblEvidence[evidence_id],tblEvidence[url],""),"")) -> #REF! | K5: =IFERROR(LOOKUP(2,1/((tblClaimCandidates[entity_id]=#REF!)*(tblClaimCandidates[field_key]=#REF!)*(tblClaimCandidates[status_final]="PROMOTED")),tblClaimCandidates[tier]),"") | L5: =IF(#REF!="UNKNOWN","UNKNOWN","PROMOTED") -> #REF! | M5: =IF(#REF!="PROMOTED",TODAY(),"") -> #REF! | N5: =IF(#REF!="PROMOTED","evidence_linked","UNKNOWN_or_unverified") -> #REF!
A6: E001 | B6: AcmeRival | C6: SEG_MM | D6: arr_estimate | E6: =_xludf.LET(v,IFERROR(LOOKUP(2,1/((tblClaimCandidates[entity_id]=#REF!)*(tblClaimCandidates[field_key]=#REF!)*(tblClaimCandidates[status_final]="PROMOTED")),tblClaimCandidates[value_text]),""),IF(v="","UNKNOWN",v)) -> #NAME? | F6: =_xludf.LET(cnt,COUNTIFS(tblClaimCandidates[entity_id],#REF!,tblClaimCandidates[field_key],#REF!,tblClaimCandidates[status_final],"PROMOTED"),IF(cnt=0,NA(),SUMIFS(tblClaimCandidates[value_num],tblClaimCandidates[entity_id],#REF!,tblClaimCandidates[field_key],#REF!,tblClaimCandidates[status_final],"PROMOTED"))) -> #NAME? | G6: =IFERROR(_xludf.XLOOKUP(#REF!,tblFieldDictionary[field_key],tblFieldDictionary[units]),"") | H6: =_xludf.LET(cnt,COUNTIFS(tblClaimCandidates[entity_id],#REF!,tblClaimCandidates[field_key],#REF!,tblClaimCandidates[status_final],"PROMOTED"),IF(cnt=0,NA(),AVERAGEIFS(tblClaimCandidates[confidence],tblClaimCandidates[entity_id],#REF!,tblClaimCandidates[field_key],#REF!,tblClaimCandidates[status_final],"PROMOTED"))) -> #NAME? | I6: =IFERROR(LOOKUP(2,1/((tblClaimCandidates[entity_id]=#REF!)*(tblClaimCandidates[field_key]=#REF!)*(tblClaimCandidates[status_final]="PROMOTED")),tblClaimCandidates[evidence_id]),"") | J6: =IF(#REF!="","",IFERROR(_xludf.XLOOKUP(#REF!,tblEvidence[evidence_id],tblEvidence[url],""),"")) -> #REF! | K6: =IFERROR(LOOKUP(2,1/((tblClaimCandidates[entity_id]=#REF!)*(tblClaimCandidates[field_key]=#REF!)*(tblClaimCandidates[status_final]="PROMOTED")),tblClaimCandidates[tier]),"") | L6: =IF(#REF!="UNKNOWN","UNKNOWN","PROMOTED") -> #REF! | M6: =IF(#REF!="PROMOTED",TODAY(),"") -> #REF! | N6: =IF(#REF!="PROMOTED","evidence_linked","UNKNOWN_or_unverified") -> #REF!
A7: E001 | B7: AcmeRival | C7: SEG_MM | D7: contract_terms | E7: =_xludf.LET(v,IFERROR(LOOKUP(2,1/((tblClaimCandidates[entity_id]=#REF!)*(tblClaimCandidates[field_key]=#REF!)*(tblClaimCandidates[status_final]="PROMOTED")),tblClaimCandidates[value_text]),""),IF(v="","UNKNOWN",v)) -> #NAME? | F7: =_xludf.LET(cnt,COUNTIFS(tblClaimCandidates[entity_id],#REF!,tblClaimCandidates[field_key],#REF!,tblClaimCandidates[status_final],"PROMOTED"),IF(cnt=0,NA(),SUMIFS(tblClaimCandidates[value_num],tblClaimCandidates[entity_id],#REF!,tblClaimCandidates[field_key],#REF!,tblClaimCandidates[status_final],"PROMOTED"))) -> #NAME? | G7: =IFERROR(_xludf.XLOOKUP(#REF!,tblFieldDictionary[field_key],tblFieldDictionary[units]),"") | H7: =_xludf.LET(cnt,COUNTIFS(tblClaimCandidates[entity_id],#REF!,tblClaimCandidates[field_key],#REF!,tblClaimCandidates[status_final],"PROMOTED"),IF(cnt=0,NA(),AVERAGEIFS(tblClaimCandidates[confidence],tblClaimCandidates[entity_id],#REF!,tblClaimCandidates[field_key],#REF!,tblClaimCandidates[status_final],"PROMOTED"))) -> #NAME? | I7: =IFERROR(LOOKUP(2,1/((tblClaimCandidates[entity_id]=#REF!)*(tblClaimCandidates[field_key]=#REF!)*(tblClaimCandidates[status_final]="PROMOTED")),tblClaimCandidates[evidence_id]),"") | J7: =IF(#REF!="","",IFERROR(_xludf.XLOOKUP(#REF!,tblEvidence[evidence_id],tblEvidence[url],""),"")) -> #REF! | K7: =IFERROR(LOOKUP(2,1/((tblClaimCandidates[entity_id]=#REF!)*(tblClaimCandidates[field_key]=#REF!)*(tblClaimCandidates[status_final]="PROMOTED")),tblClaimCandidates[tier]),"") | L7: =IF(#REF!="UNKNOWN","UNKNOWN","PROMOTED") -> #REF! | M7: =IF(#REF!="PROMOTED",TODAY(),"") -> #REF! | N7: =IF(#REF!="PROMOTED","evidence_linked","UNKNOWN_or_unverified") -> #REF!
A8: E001 | B8: AcmeRival | C8: SEG_MM | D8: features | E8: =_xludf.LET(v,IFERROR(LOOKUP(2,1/((tblClaimCandidates[entity_id]=#REF!)*(tblClaimCandidates[field_key]=#REF!)*(tblClaimCandidates[status_final]="PROMOTED")),tblClaimCandidates[value_text]),""),IF(v="","UNKNOWN",v)) -> #NAME? | F8: =_xludf.LET(cnt,COUNTIFS(tblClaimCandidates[entity_id],#REF!,tblClaimCandidates[field_key],#REF!,tblClaimCandidates[status_final],"PROMOTED"),IF(cnt=0,NA(),SUMIFS(tblClaimCandidates[value_num],tblClaimCandidates[entity_id],#REF!,tblClaimCandidates[field_key],#REF!,tblClaimCandidates[status_final],"PROMOTED"))) -> #NAME? | G8: =IFERROR(_xludf.XLOOKUP(#REF!,tblFieldDictionary[field_key],tblFieldDictionary[units]),"") | H8: =_xludf.LET(cnt,COUNTIFS(tblClaimCandidates[entity_id],#REF!,tblClaimCandidates[field_key],#REF!,tblClaimCandidates[status_final],"PROMOTED"),IF(cnt=0,NA(),AVERAGEIFS(tblClaimCandidates[confidence],tblClaimCandidates[entity_id],#REF!,tblClaimCandidates[field_key],#REF!,tblClaimCandidates[status_final],"PROMOTED"))) -> #NAME? | I8: =IFERROR(LOOKUP(2,1/((tblClaimCandidates[entity_id]=#REF!)*(tblClaimCandidates[field_key]=#REF!)*(tblClaimCandidates[status_final]="PROMOTED")),tblClaimCandidates[evidence_id]),"") | J8: =IF(#REF!="","",IFERROR(_xludf.XLOOKUP(#REF!,tblEvidence[evidence_id],tblEvidence[url],""),"")) -> #REF! | K8: =IFERROR(LOOKUP(2,1/((tblClaimCandidates[entity_id]=#REF!)*(tblClaimCandidates[field_key]=#REF!)*(tblClaimCandidates[status_final]="PROMOTED")),tblClaimCandidates[tier]),"") | L8: =IF(#REF!="UNKNOWN","UNKNOWN","PROMOTED") -> #REF! | M8: =IF(#REF!="PROMOTED",TODAY(),"") -> #REF! | N8: =IF(#REF!="PROMOTED","evidence_linked","UNKNOWN_or_unverified") -> #REF!
A9: E001 | B9: AcmeRival | C9: SEG_MM | D9: funding_round | E9: =_xludf.LET(v,IFERROR(LOOKUP(2,1/((tblClaimCandidates[entity_id]=#REF!)*(tblClaimCandidates[field_key]=#REF!)*(tblClaimCandidates[status_final]="PROMOTED")),tblClaimCandidates[value_text]),""),IF(v="","UNKNOWN",v)) -> #NAME? | F9: =_xludf.LET(cnt,COUNTIFS(tblClaimCandidates[entity_id],#REF!,tblClaimCandidates[field_key],#REF!,tblClaimCandidates[status_final],"PROMOTED"),IF(cnt=0,NA(),SUMIFS(tblClaimCandidates[value_num],tblClaimCandidates[entity_id],#REF!,tblClaimCandidates[field_key],#REF!,tblClaimCandidates[status_final],"PROMOTED"))) -> #NAME? | G9: =IFERROR(_xludf.XLOOKUP(#REF!,tblFieldDictionary[field_key],tblFieldDictionary[units]),"") | H9: =_xludf.LET(cnt,COUNTIFS(tblClaimCandidates[entity_id],#REF!,tblClaimCandidates[field_key],#REF!,tblClaimCandidates[status_final],"PROMOTED"),IF(cnt=0,NA(),AVERAGEIFS(tblClaimCandidates[confidence],tblClaimCandidates[entity_id],#REF!,tblClaimCandidates[field_key],#REF!,tblClaimCandidates[status_final],"PROMOTED"))) -> #NAME? | I9: =IFERROR(LOOKUP(2,1/((tblClaimCandidates[entity_id]=#REF!)*(tblClaimCandidates[field_key]=#REF!)*(tblClaimCandidates[status_final]="PROMOTED")),tblClaimCandidates[evidence_id]),"") | J9: =IF(#REF!="","",IFERROR(_xludf.XLOOKUP(#REF!,tblEvidence[evidence_id],tblEvidence[url],""),"")) -> #REF! | K9: =IFERROR(LOOKUP(2,1/((tblClaimCandidates[entity_id]=#REF!)*(tblClaimCandidates[field_key]=#REF!)*(tblClaimCandidates[status_final]="PROMOTED")),tblClaimCandidates[tier]),"") | L9: =IF(#REF!="UNKNOWN","UNKNOWN","PROMOTED") -> #REF! | M9: =IF(#REF!="PROMOTED",TODAY(),"") -> #REF! | N9: =IF(#REF!="PROMOTED","evidence_linked","UNKNOWN_or_unverified") -> #REF!
A10: E001 | B10: AcmeRival | C10: SEG_MM | D10: geo_coverage | E10: =_xludf.LET(v,IFERROR(LOOKUP(2,1/((tblClaimCandidates[entity_id]=#REF!)*(tblClaimCandidates[field_key]=#REF!)*(tblClaimCandidates[status_final]="PROMOTED")),tblClaimCandidates[value_text]),""),IF(v="","UNKNOWN",v)) -> #NAME? | F10: =_xludf.LET(cnt,COUNTIFS(tblClaimCandidates[entity_id],#REF!,tblClaimCandidates[field_key],#REF!,tblClaimCandidates[status_final],"PROMOTED"),IF(cnt=0,NA(),SUMIFS(tblClaimCandidates[value_num],tblClaimCandidates[entity_id],#REF!,tblClaimCandidates[field_key],#REF!,tblClaimCandidates[status_final],"PROMOTED"))) -> #NAME? | G10: =IFERROR(_xludf.XLOOKUP(#REF!,tblFieldDictionary[field_key],tblFieldDictionary[units]),"") | H10: =_xludf.LET(cnt,COUNTIFS(tblClaimCandidates[entity_id],#REF!,tblClaimCandidates[field_key],#REF!,tblClaimCandidates[status_final],"PROMOTED"),IF(cnt=0,NA(),AVERAGEIFS(tblClaimCandidates[confidence],tblClaimCandidates[entity_id],#REF!,tblClaimCandidates[field_key],#REF!,tblClaimCandidates[status_final],"PROMOTED"))) -> #NAME? | I10: =IFERROR(LOOKUP(2,1/((tblClaimCandidates[entity_id]=#REF!)*(tblClaimCandidates[field_key]=#REF!)*(tblClaimCandidates[status_final]="PROMOTED")),tblClaimCandidates[evidence_id]),"") | J10: =IF(#REF!="","",IFERROR(_xludf.XLOOKUP(#REF!,tblEvidence[evidence_id],tblEvidence[url],""),"")) -> #REF! | K10: =IFERROR(LOOKUP(2,1/((tblClaimCandidates[entity_id]=#REF!)*(tblClaimCandidates[field_key]=#REF!)*(tblClaimCandidates[status_final]="PROMOTED")),tblClaimCandidates[tier]),"") | L10: =IF(#REF!="UNKNOWN","UNKNOWN","PROMOTED") -> #REF! | M10: =IF(#REF!="PROMOTED",TODAY(),"") -> #REF! | N10: =IF(#REF!="PROMOTED","evidence_linked","UNKNOWN_or_unverified") -> #REF!
A11: E001 | B11: AcmeRival | C11: SEG_MM | D11: practice_size_target | E11: =_xludf.LET(v,IFERROR(LOOKUP(2,1/((tblClaimCandidates[entity_id]=#REF!)*(tblClaimCandidates[field_key]=#REF!)*(tblClaimCandidates[status_final]="PROMOTED")),tblClaimCandidates[value_text]),""),IF(v="","UNKNOWN",v)) -> #NAME? | F11: =_xludf.LET(cnt,COUNTIFS(tblClaimCandidates[entity_id],#REF!,tblClaimCandidates[field_key],#REF!,tblClaimCandidates[status_final],"PROMOTED"),IF(cnt=0,NA(),SUMIFS(tblClaimCandidates[value_num],tblClaimCandidates[entity_id],#REF!,tblClaimCandidates[field_key],#REF!,tblClaimCandidates[status_final],"PROMOTED"))) -> #NAME? | G11: =IFERROR(_xludf.XLOOKUP(#REF!,tblFieldDictionary[field_key],tblFieldDictionary[units]),"") | H11: =_xludf.LET(cnt,COUNTIFS(tblClaimCandidates[entity_id],#REF!,tblClaimCandidates[field_key],#REF!,tblClaimCandidates[status_final],"PROMOTED"),IF(cnt=0,NA(),AVERAGEIFS(tblClaimCandidates[confidence],tblClaimCandidates[entity_id],#REF!,tblClaimCandidates[field_key],#REF!,tblClaimCandidates[status_final],"PROMOTED"))) -> #NAME? | I11: =IFERROR(LOOKUP(2,1/((tblClaimCandidates[entity_id]=#REF!)*(tblClaimCandidates[field_key]=#REF!)*(tblClaimCandidates[status_final]="PROMOTED")),tblClaimCandidates[evidence_id]),"") | J11: =IF(#REF!="","",IFERROR(_xludf.XLOOKUP(#REF!,tblEvidence[evidence_id],tblEvidence[url],""),"")) -> #REF! | K11: =IFERROR(LOOKUP(2,1/((tblClaimCandidates[entity_id]=#REF!)*(tblClaimCandidates[field_key]=#REF!)*(tblClaimCandidates[status_final]="PROMOTED")),tblClaimCandidates[tier]),"") | L11: =IF(#REF!="UNKNOWN","UNKNOWN","PROMOTED") -> #REF! | M11: =IF(#REF!="PROMOTED",TODAY(),"") -> #REF! | N11: =IF(#REF!="PROMOTED","evidence_linked","UNKNOWN_or_unverified") -> #REF!
A12: E002 | B12: EnrollPro | C12: SEG_MM | D12: pricing_acv_mid_market | E12: =_xludf.LET(v,IFERROR(LOOKUP(2,1/((tblClaimCandidates[entity_id]=#REF!)*(tblClaimCandidates[field_key]=#REF!)*(tblClaimCandidates[status_final]="PROMOTED")),tblClaimCandidates[value_text]),""),IF(v="","UNKNOWN",v)) -> #NAME? | F12: =_xludf.LET(cnt,COUNTIFS(tblClaimCandidates[entity_id],#REF!,tblClaimCandidates[field_key],#REF!,tblClaimCandidates[status_final],"PROMOTED"),IF(cnt=0,NA(),SUMIFS(tblClaimCandidates[value_num],tblClaimCandidates[entity_id],#REF!,tblClaimCandidates[field_key],#REF!,tblClaimCandidates[status_final],"PROMOTED"))) -> #NAME? | G12: =IFERROR(_xludf.XLOOKUP(#REF!,tblFieldDictionary[field_key],tblFieldDictionary[units]),"") | H12: =_xludf.LET(cnt,COUNTIFS(tblClaimCandidates[entity_id],#REF!,tblClaimCandidates[field_key],#REF!,tblClaimCandidates[status_final],"PROMOTED"),IF(cnt=0,NA(),AVERAGEIFS(tblClaimCandidates[confidence],tblClaimCandidates[entity_id],#REF!,tblClaimCandidates[field_key],#REF!,tblClaimCandidates[status_final],"PROMOTED"))) -> #NAME? | I12: =IFERROR(LOOKUP(2,1/((tblClaimCandidates[entity_id]=#REF!)*(tblClaimCandidates[field_key]=#REF!)*(tblClaimCandidates[status_final]="PROMOTED")),tblClaimCandidates[evidence_id]),"") | J12: =IF(#REF!="","",IFERROR(_xludf.XLOOKUP(#REF!,tblEvidence[evidence_id],tblEvidence[url],""),"")) -> #REF! | K12: =IFERROR(LOOKUP(2,1/((tblClaimCandidates[entity_id]=#REF!)*(tblClaimCandidates[field_key]=#REF!)*(tblClaimCandidates[status_final]="PROMOTED")),tblClaimCandidates[tier]),"") | L12: =IF(#REF!="UNKNOWN","UNKNOWN","PROMOTED") -> #REF! | M12: =IF(#REF!="PROMOTED",TODAY(),"") -> #REF! | N12: =IF(#REF!="PROMOTED","evidence_linked","UNKNOWN_or_unverified") -> #REF!
A13: E002 | B13: EnrollPro | C13: SEG_MM | D13: arr_estimate | E13: =_xludf.LET(v,IFERROR(LOOKUP(2,1/((tblClaimCandidates[entity_id]=#REF!)*(tblClaimCandidates[field_key]=#REF!)*(tblClaimCandidates[status_final]="PROMOTED")),tblClaimCandidates[value_text]),""),IF(v="","UNKNOWN",v)) -> #NAME? | F13: =_xludf.LET(cnt,COUNTIFS(tblClaimCandidates[entity_id],#REF!,tblClaimCandidates[field_key],#REF!,tblClaimCandidates[status_final],"PROMOTED"),IF(cnt=0,NA(),SUMIFS(tblClaimCandidates[value_num],tblClaimCandidates[entity_id],#REF!,tblClaimCandidates[field_key],#REF!,tblClaimCandidates[status_final],"PROMOTED"))) -> #NAME? | G13: =IFERROR(_xludf.XLOOKUP(#REF!,tblFieldDictionary[field_key],tblFieldDictionary[units]),"") | H13: =_xludf.LET(cnt,COUNTIFS(tblClaimCandidates[entity_id],#REF!,tblClaimCandidates[field_key],#REF!,tblClaimCandidates[status_final],"PROMOTED"),IF(cnt=0,NA(),AVERAGEIFS(tblClaimCandidates[confidence],tblClaimCandidates[entity_id],#REF!,tblClaimCandidates[field_key],#REF!,tblClaimCandidates[status_final],"PROMOTED"))) -> #NAME? | I13: =IFERROR(LOOKUP(2,1/((tblClaimCandidates[entity_id]=#REF!)*(tblClaimCandidates[field_key]=#REF!)*(tblClaimCandidates[status_final]="PROMOTED")),tblClaimCandidates[evidence_id]),"") | J13: =IF(#REF!="","",IFERROR(_xludf.XLOOKUP(#REF!,tblEvidence[evidence_id],tblEvidence[url],""),"")) -> #REF! | K13: =IFERROR(LOOKUP(2,1/((tblClaimCandidates[entity_id]=#REF!)*(tblClaimCandidates[field_key]=#REF!)*(tblClaimCandidates[status_final]="PROMOTED")),tblClaimCandidates[tier]),"") | L13: =IF(#REF!="UNKNOWN","UNKNOWN","PROMOTED") -> #REF! | M13: =IF(#REF!="PROMOTED",TODAY(),"") -> #REF! | N13: =IF(#REF!="PROMOTED","evidence_linked","UNKNOWN_or_unverified") -> #REF!
A14: E002 | B14: EnrollPro | C14: SEG_MM | D14: contract_terms | E14: =_xludf.LET(v,IFERROR(LOOKUP(2,1/((tblClaimCandidates[entity_id]=#REF!)*(tblClaimCandidates[field_key]=#REF!)*(tblClaimCandidates[status_final]="PROMOTED")),tblClaimCandidates[value_text]),""),IF(v="","UNKNOWN",v)) -> #NAME? | F14: =_xludf.LET(cnt,COUNTIFS(tblClaimCandidates[entity_id],#REF!,tblClaimCandidates[field_key],#REF!,tblClaimCandidates[status_final],"PROMOTED"),IF(cnt=0,NA(),SUMIFS(tblClaimCandidates[value_num],tblClaimCandidates[entity_id],#REF!,tblClaimCandidates[field_key],#REF!,tblClaimCandidates[status_final],"PROMOTED"))) -> #NAME? | G14: =IFERROR(_xludf.XLOOKUP(#REF!,tblFieldDictionary[field_key],tblFieldDictionary[units]),"") | H14: =_xludf.LET(cnt,COUNTIFS(tblClaimCandidates[entity_id],#REF!,tblClaimCandidates[field_key],#REF!,tblClaimCandidates[status_final],"PROMOTED"),IF(cnt=0,NA(),AVERAGEIFS(tblClaimCandidates[confidence],tblClaimCandidates[entity_id],#REF!,tblClaimCandidates[field_key],#REF!,tblClaimCandidates[status_final],"PROMOTED"))) -> #NAME? | I14: =IFERROR(LOOKUP(2,1/((tblClaimCandidates[entity_id]=#REF!)*(tblClaimCandidates[field_key]=#REF!)*(tblClaimCandidates[status_final]="PROMOTED")),tblClaimCandidates[evidence_id]),"") | J14: =IF(#REF!="","",IFERROR(_xludf.XLOOKUP(#REF!,tblEvidence[evidence_id],tblEvidence[url],""),"")) -> #REF! | K14: =IFERROR(LOOKUP(2,1/((tblClaimCandidates[entity_id]=#REF!)*(tblClaimCandidates[field_key]=#REF!)*(tblClaimCandidates[status_final]="PROMOTED")),tblClaimCandidates[tier]),"") | L14: =IF(#REF!="UNKNOWN","UNKNOWN","PROMOTED") -> #REF! | M14: =IF(#REF!="PROMOTED",TODAY(),"") -> #REF! | N14: =IF(#REF!="PROMOTED","evidence_linked","UNKNOWN_or_unverified") -> #REF!
A15: E002 | B15: EnrollPro | C15: SEG_MM | D15: features | E15: =_xludf.LET(v,IFERROR(LOOKUP(2,1/((tblClaimCandidates[entity_id]=#REF!)*(tblClaimCandidates[field_key]=#REF!)*(tblClaimCandidates[status_final]="PROMOTED")),tblClaimCandidates[value_text]),""),IF(v="","UNKNOWN",v)) -> #NAME? | F15: =_xludf.LET(cnt,COUNTIFS(tblClaimCandidates[entity_id],#REF!,tblClaimCandidates[field_key],#REF!,tblClaimCandidates[status_final],"PROMOTED"),IF(cnt=0,NA(),SUMIFS(tblClaimCandidates[value_num],tblClaimCandidates[entity_id],#REF!,tblClaimCandidates[field_key],#REF!,tblClaimCandidates[status_final],"PROMOTED"))) -> #NAME? | G15: =IFERROR(_xludf.XLOOKUP(#REF!,tblFieldDictionary[field_key],tblFieldDictionary[units]),"") | H15: =_xludf.LET(cnt,COUNTIFS(tblClaimCandidates[entity_id],#REF!,tblClaimCandidates[field_key],#REF!,tblClaimCandidates[status_final],"PROMOTED"),IF(cnt=0,NA(),AVERAGEIFS(tblClaimCandidates[confidence],tblClaimCandidates[entity_id],#REF!,tblClaimCandidates[field_key],#REF!,tblClaimCandidates[status_final],"PROMOTED"))) -> #NAME? | I15: =IFERROR(LOOKUP(2,1/((tblClaimCandidates[entity_id]=#REF!)*(tblClaimCandidates[field_key]=#REF!)*(tblClaimCandidates[status_final]="PROMOTED")),tblClaimCandidates[evidence_id]),"") | J15: =IF(#REF!="","",IFERROR(_xludf.XLOOKUP(#REF!,tblEvidence[evidence_id],tblEvidence[url],""),"")) -> #REF! | K15: =IFERROR(LOOKUP(2,1/((tblClaimCandidates[entity_id]=#REF!)*(tblClaimCandidates[field_key]=#REF!)*(tblClaimCandidates[status_final]="PROMOTED")),tblClaimCandidates[tier]),"") | L15: =IF(#REF!="UNKNOWN","UNKNOWN","PROMOTED") -> #REF! | M15: =IF(#REF!="PROMOTED",TODAY(),"") -> #REF! | N15: =IF(#REF!="PROMOTED","evidence_linked","UNKNOWN_or_unverified") -> #REF!
A16: E002 | B16: EnrollPro | C16: SEG_MM | D16: funding_round | E16: =_xludf.LET(v,IFERROR(LOOKUP(2,1/((tblClaimCandidates[entity_id]=#REF!)*(tblClaimCandidates[field_key]=#REF!)*(tblClaimCandidates[status_final]="PROMOTED")),tblClaimCandidates[value_text]),""),IF(v="","UNKNOWN",v)) -> #NAME? | F16: =_xludf.LET(cnt,COUNTIFS(tblClaimCandidates[entity_id],#REF!,tblClaimCandidates[field_key],#REF!,tblClaimCandidates[status_final],"PROMOTED"),IF(cnt=0,NA(),SUMIFS(tblClaimCandidates[value_num],tblClaimCandidates[entity_id],#REF!,tblClaimCandidates[field_key],#REF!,tblClaimCandidates[status_final],"PROMOTED"))) -> #NAME? | G16: =IFERROR(_xludf.XLOOKUP(#REF!,tblFieldDictionary[field_key],tblFieldDictionary[units]),"") | H16: =_xludf.LET(cnt,COUNTIFS(tblClaimCandidates[entity_id],#REF!,tblClaimCandidates[field_key],#REF!,tblClaimCandidates[status_final],"PROMOTED"),IF(cnt=0,NA(),AVERAGEIFS(tblClaimCandidates[confidence],tblClaimCandidates[entity_id],#REF!,tblClaimCandidates[field_key],#REF!,tblClaimCandidates[status_final],"PROMOTED"))) -> #NAME? | I16: =IFERROR(LOOKUP(2,1/((tblClaimCandidates[entity_id]=#REF!)*(tblClaimCandidates[field_key]=#REF!)*(tblClaimCandidates[status_final]="PROMOTED")),tblClaimCandidates[evidence_id]),"") | J16: =IF(#REF!="","",IFERROR(_xludf.XLOOKUP(#REF!,tblEvidence[evidence_id],tblEvidence[url],""),"")) -> #REF! | K16: =IFERROR(LOOKUP(2,1/((tblClaimCandidates[entity_id]=#REF!)*(tblClaimCandidates[field_key]=#REF!)*(tblClaimCandidates[status_final]="PROMOTED")),tblClaimCandidates[tier]),"") | L16: =IF(#REF!="UNKNOWN","UNKNOWN","PROMOTED") -> #REF! | M16: =IF(#REF!="PROMOTED",TODAY(),"") -> #REF! | N16: =IF(#REF!="PROMOTED","evidence_linked","UNKNOWN_or_unverified") -> #REF!
... A46: E006 | B46: MidMarketMedTech | C46: SEG_MM | D46: practice_size_target | E46: =_xludf.LET(v,IFERROR(LOOKUP(2,1/((tblClaimCandidates[entity_id]=#REF!)*(tblClaimCandidates[field_key]=#REF!)*(tblClaimCandidates[status_final]="PROMOTED")),tblClaimCandidates[value_text]),""),IF(v="","UNKNOWN",v)) -> #NAME? | F46: =_xludf.LET(cnt,COUNTIFS(tblClaimCandidates[entity_id],#REF!,tblClaimCandidates[field_key],#REF!,tblClaimCandidates[status_final],"PROMOTED"),IF(cnt=0,NA(),SUMIFS(tblClaimCandidates[value_num],tblClaimCandidates[entity_id],#REF!,tblClaimCandidates[field_key],#REF!,tblClaimCandidates[status_final],"PROMOTED"))) -> #NAME? | G46: =IFERROR(_xludf.XLOOKUP(#REF!,tblFieldDictionary[field_key],tblFieldDictionary[units]),"") | H46: =_xludf.LET(cnt,COUNTIFS(tblClaimCandidates[entity_id],#REF!,tblClaimCandidates[field_key],#REF!,tblClaimCandidates[status_final],"PROMOTED"),IF(cnt=0,NA(),AVERAGEIFS(tblClaimCandidates[confidence],tblClaimCandidates[entity_id],#REF!,tblClaimCandidates[field_key],#REF!,tblClaimCandidates[status_final],"PROMOTED"))) -> #NAME? | I46: =IFERROR(LOOKUP(2,1/((tblClaimCandidates[entity_id]=#REF!)*(tblClaimCandidates[field_key]=#REF!)*(tblClaimCandidates[status_final]="PROMOTED")),tblClaimCandidates[evidence_id]),"") | J46: =IF(#REF!="","",IFERROR(_xludf.XLOOKUP(#REF!,tblEvidence[evidence_id],tblEvidence[url],""),"")) -> #REF! | K46: =IFERROR(LOOKUP(2,1/((tblClaimCandidates[entity_id]=#REF!)*(tblClaimCandidates[field_key]=#REF!)*(tblClaimCandidates[status_final]="PROMOTED")),tblClaimCandidates[tier]),"") | L46: =IF(#REF!="UNKNOWN","UNKNOWN","PROMOTED") -> #REF! | M46: =IF(#REF!="PROMOTED",TODAY(),"") -> #REF! | N46: =IF(#REF!="PROMOTED","evidence_linked","UNKNOWN_or_unverified") -> #REF!

Sheet Metrics
A1: Metrics (Derived; Formula-Driven)
A2: All figures are derived from Claims_Current (which must be evidence-backed). UNKNOWN propagates to Review Queue and fail-closed flags.
A4: Global Drivers
A5: Median ACV (USD/year) | D5: Evidence Freshness Threshold (days) | E5: =Config!$B$9 -> 30 | G5: Min Coverage (fail-closed) | H5: =Config!$B$10 -> 0.6
A7: entity_id | B7: canonical_name | C7: known_claims | D7: unknown_claims | E7: coverage_pct | F7: avg_conf | G7: acv_usd | H7: acv_band | I7: features_text | J7: feature_count | K7: segment_fit | L7: funding_present | M7: threat_score | N7: opportunity_score | O7: flags | P7: segment_id | Q7: vertical | R7: in_scope | AA7: competitors_in_scope
A8: =IF(Input!$A$7="","",Input!$A$7) -> E001 | B8: =IFERROR(_xludf.XLOOKUP(#REF!,tblEntities[entity_id],tblEntities[canonical_name]),"") | C8: =IF(#REF!="","",COUNTIFS(tblClaimsCurrent[entity_id],#REF!,tblClaimsCurrent[status],"PROMOTED")) -> #REF! | D8: =IF(#REF!="","",COUNTIFS(tblClaimsCurrent[entity_id],#REF!,tblClaimsCurrent[status],"UNKNOWN")) -> #REF! | E8: =_xludf.LET(t,#REF!+#REF!,IF(t=0,NA(),#REF!/t)) -> #NAME? | F8: =_xludf.LET(cnt,COUNTIFS(tblClaimsCurrent[entity_id],#REF!,tblClaimsCurrent[status],"PROMOTED"),IF(cnt=0,NA(),AVERAGEIFS(tblClaimsCurrent[confidence],tblClaimsCurrent[entity_id],#REF!,tblClaimsCurrent[status],"PROMOTED"))) -> #NAME? | G8: =_xludf.LET(cnt,COUNTIFS(tblClaimsCurrent[entity_id],#REF!,tblClaimsCurrent[field_key],"pricing_acv_mid_market",tblClaimsCurrent[status],"PROMOTED"),IF(cnt=0,NA(),SUMIFS(tblClaimsCurrent[value_num],tblClaimsCurrent[entity_id],#REF!,tblClaimsCurrent[field_key],"pricing_acv_mid_market",tblClaimsCurrent[status],"PROMOTED"))) -> #NAME? | H8: =IF(OR(NOT(ISNUMBER(#REF!)),$B$5=""),"UNKNOWN",IF(#REF!<=($B$5*0.85),"Low",IF(#REF!>=($B$5*1.15),"High","Mid"))) -> UNKNOWN | I8: =_xludf.LET(v,IFERROR(LOOKUP(2,1/((tblClaimsCurrent[entity_id]=#REF!)*(tblClaimsCurrent[field_key]="features")*(tblClaimsCurrent[status]="PROMOTED")),tblClaimsCurrent[value_text]),"UNKNOWN"),IF(v="","UNKNOWN",v)) -> #NAME? | J8: =IF(OR(#REF!="UNKNOWN",#REF!=""),NA(),1+LEN(#REF!)-LEN(SUBSTITUTE(#REF!,";",""))) -> #REF! | K8: =IF(#REF!="",NA(),IF(#REF!="SEG_MM",1,0)) -> #REF! | L8: =IF(#REF!="","",IF(COUNTIFS(tblClaimsCurrent[entity_id],#REF!,tblClaimsCurrent[field_key],"funding_round",tblClaimsCurrent[status],"PROMOTED")>0,1,0)) -> #REF! | M8: =IF(OR(#REF!=FALSE,ISNA(#REF!),ISNA(#REF!),ISNA(#REF!),#REF!="UNKNOWN"),NA(),MIN(1,Config!$B$14*MIN(1,#REF!/10)+Config!$B$15*IF(#REF!="Low",1,IF(#REF!="Mid",0.5,0))+Config!$B$16*#REF!+Config!$B$17*#REF!)) -> #REF! | N8: =IF(OR(#REF!=FALSE,ISNA(#REF!),ISNA(#REF!),ISNA(#REF!)),NA(),MIN(1,Config!$B$18*(1-MIN(1,#REF!/10))+Config!$B$19*(1-#REF!)+Config!$B$20*(1-#REF!))) -> #REF! | O8: =IF(#REF!=FALSE,"OUT_OF_SCOPE",IF(ISNA(#REF!),"UNKNOWN",IF(#REF!<Config!$B$10,"FAIL_CLOSED_LOW_COVERAGE","OK"))) -> #REF! | P8: =IFERROR(_xludf.XLOOKUP(#REF!,tblEntities[entity_id],tblEntities[segment_id]),"") | Q8: =IFERROR(_xludf.XLOOKUP(#REF!,tblEntities[entity_id],tblEntities[vertical]),"") | R8: =AND(#REF!=Dashboard!$E$2,IF(Dashboard!$E$3="All",TRUE,#REF!=Dashboard!$E$3)) -> #REF!
A9: =IF(Input!$A$8="","",Input!$A$8) -> E002 | B9: =IFERROR(_xludf.XLOOKUP(#REF!,tblEntities[entity_id],tblEntities[canonical_name]),"") | C9: =IF(#REF!="","",COUNTIFS(tblClaimsCurrent[entity_id],#REF!,tblClaimsCurrent[status],"PROMOTED")) -> #REF! | D9: =IF(#REF!="","",COUNTIFS(tblClaimsCurrent[entity_id],#REF!,tblClaimsCurrent[status],"UNKNOWN")) -> #REF! | E9: =_xludf.LET(t,#REF!+#REF!,IF(t=0,NA(),#REF!/t)) -> #NAME? | F9: =_xludf.LET(cnt,COUNTIFS(tblClaimsCurrent[entity_id],#REF!,tblClaimsCurrent[status],"PROMOTED"),IF(cnt=0,NA(),AVERAGEIFS(tblClaimsCurrent[confidence],tblClaimsCurrent[entity_id],#REF!,tblClaimsCurrent[status],"PROMOTED"))) -> #NAME? | G9: =_xludf.LET(cnt,COUNTIFS(tblClaimsCurrent[entity_id],#REF!,tblClaimsCurrent[field_key],"pricing_acv_mid_market",tblClaimsCurrent[status],"PROMOTED"),IF(cnt=0,NA(),SUMIFS(tblClaimsCurrent[value_num],tblClaimsCurrent[entity_id],#REF!,tblClaimsCurrent[field_key],"pricing_acv_mid_market",tblClaimsCurrent[status],"PROMOTED"))) -> #NAME? | H9: =IF(OR(NOT(ISNUMBER(#REF!)),$B$5=""),"UNKNOWN",IF(#REF!<=($B$5*0.85),"Low",IF(#REF!>=($B$5*1.15),"High","Mid"))) -> UNKNOWN | I9: =_xludf.LET(v,IFERROR(LOOKUP(2,1/((tblClaimsCurrent[entity_id]=#REF!)*(tblClaimsCurrent[field_key]="features")*(tblClaimsCurrent[status]="PROMOTED")),tblClaimsCurrent[value_text]),"UNKNOWN"),IF(v="","UNKNOWN",v)) -> #NAME? | J9: =IF(OR(#REF!="UNKNOWN",#REF!=""),NA(),1+LEN(#REF!)-LEN(SUBSTITUTE(#REF!,";",""))) -> #REF! | K9: =IF(#REF!="",NA(),IF(#REF!="SEG_MM",1,0)) -> #REF! | L9: =IF(#REF!="","",IF(COUNTIFS(tblClaimsCurrent[entity_id],#REF!,tblClaimsCurrent[field_key],"funding_round",tblClaimsCurrent[status],"PROMOTED")>0,1,0)) -> #REF! | M9: =IF(OR(#REF!=FALSE,ISNA(#REF!),ISNA(#REF!),ISNA(#REF!),#REF!="UNKNOWN"),NA(),MIN(1,Config!$B$14*MIN(1,#REF!/10)+Config!$B$15*IF(#REF!="Low",1,IF(#REF!="Mid",0.5,0))+Config!$B$16*#REF!+Config!$B$17*#REF!)) -> #REF! | N9: =IF(OR(#REF!=FALSE,ISNA(#REF!),ISNA(#REF!),ISNA(#REF!)),NA(),MIN(1,Config!$B$18*(1-MIN(1,#REF!/10))+Config!$B$19*(1-#REF!)+Config!$B$20*(1-#REF!))) -> #REF! | O9: =IF(#REF!=FALSE,"OUT_OF_SCOPE",IF(ISNA(#REF!),"UNKNOWN",IF(#REF!<Config!$B$10,"FAIL_CLOSED_LOW_COVERAGE","OK"))) -> #REF! | P9: =IFERROR(_xludf.XLOOKUP(#REF!,tblEntities[entity_id],tblEntities[segment_id]),"") | Q9: =IFERROR(_xludf.XLOOKUP(#REF!,tblEntities[entity_id],tblEntities[vertical]),"") | R9: =AND(#REF!=Dashboard!$E$2,IF(Dashboard!$E$3="All",TRUE,#REF!=Dashboard!$E$3)) -> #REF!
A10: =IF(Input!$A$9="","",Input!$A$9) -> E003 | B10: =IFERROR(_xludf.XLOOKUP(#REF!,tblEntities[entity_id],tblEntities[canonical_name]),"") | C10: =IF(#REF!="","",COUNTIFS(tblClaimsCurrent[entity_id],#REF!,tblClaimsCurrent[status],"PROMOTED")) -> #REF! | D10: =IF(#REF!="","",COUNTIFS(tblClaimsCurrent[entity_id],#REF!,tblClaimsCurrent[status],"UNKNOWN")) -> #REF! | E10: =_xludf.LET(t,#REF!+#REF!,IF(t=0,NA(),#REF!/t)) -> #NAME? | F10: =_xludf.LET(cnt,COUNTIFS(tblClaimsCurrent[entity_id],#REF!,tblClaimsCurrent[status],"PROMOTED"),IF(cnt=0,NA(),AVERAGEIFS(tblClaimsCurrent[confidence],tblClaimsCurrent[entity_id],#REF!,tblClaimsCurrent[status],"PROMOTED"))) -> #NAME? | G10: =_xludf.LET(cnt,COUNTIFS(tblClaimsCurrent[entity_id],#REF!,tblClaimsCurrent[field_key],"pricing_acv_mid_market",tblClaimsCurrent[status],"PROMOTED"),IF(cnt=0,NA(),SUMIFS(tblClaimsCurrent[value_num],tblClaimsCurrent[entity_id],#REF!,tblClaimsCurrent[field_key],"pricing_acv_mid_market",tblClaimsCurrent[status],"PROMOTED"))) -> #NAME? | H10: =IF(OR(NOT(ISNUMBER(#REF!)),$B$5=""),"UNKNOWN",IF(#REF!<=($B$5*0.85),"Low",IF(#REF!>=($B$5*1.15),"High","Mid"))) -> UNKNOWN | I10: =_xludf.LET(v,IFERROR(LOOKUP(2,1/((tblClaimsCurrent[entity_id]=#REF!)*(tblClaimsCurrent[field_key]="features")*(tblClaimsCurrent[status]="PROMOTED")),tblClaimsCurrent[value_text]),"UNKNOWN"),IF(v="","UNKNOWN",v)) -> #NAME? | J10: =IF(OR(#REF!="UNKNOWN",#REF!=""),NA(),1+LEN(#REF!)-LEN(SUBSTITUTE(#REF!,";",""))) -> #REF! | K10: =IF(#REF!="",NA(),IF(#REF!="SEG_MM",1,0)) -> #REF! | L10: =IF(#REF!="","",IF(COUNTIFS(tblClaimsCurrent[entity_id],#REF!,tblClaimsCurrent[field_key],"funding_round",tblClaimsCurrent[status],"PROMOTED")>0,1,0)) -> #REF! | M10: =IF(OR(#REF!=FALSE,ISNA(#REF!),ISNA(#REF!),ISNA(#REF!),#REF!="UNKNOWN"),NA(),MIN(1,Config!$B$14*MIN(1,#REF!/10)+Config!$B$15*IF(#REF!="Low",1,IF(#REF!="Mid",0.5,0))+Config!$B$16*#REF!+Config!$B$17*#REF!)) -> #REF! | N10: =IF(OR(#REF!=FALSE,ISNA(#REF!),ISNA(#REF!),ISNA(#REF!)),NA(),MIN(1,Config!$B$18*(1-MIN(1,#REF!/10))+Config!$B$19*(1-#REF!)+Config!$B$20*(1-#REF!))) -> #REF! | O10: =IF(#REF!=FALSE,"OUT_OF_SCOPE",IF(ISNA(#REF!),"UNKNOWN",IF(#REF!<Config!$B$10,"FAIL_CLOSED_LOW_COVERAGE","OK"))) -> #REF! | P10: =IFERROR(_xludf.XLOOKUP(#REF!,tblEntities[entity_id],tblEntities[segment_id]),"") | Q10: =IFERROR(_xludf.XLOOKUP(#REF!,tblEntities[entity_id],tblEntities[vertical]),"") | R10: =AND(#REF!=Dashboard!$E$2,IF(Dashboard!$E$3="All",TRUE,#REF!=Dashboard!$E$3)) -> #REF!
A11: =IF(Input!$A$10="","",Input!$A$10) -> E004 | B11: =IFERROR(_xludf.XLOOKUP(#REF!,tblEntities[entity_id],tblEntities[canonical_name]),"") | C11: =IF(#REF!="","",COUNTIFS(tblClaimsCurrent[entity_id],#REF!,tblClaimsCurrent[status],"PROMOTED")) -> #REF! | D11: =IF(#REF!="","",COUNTIFS(tblClaimsCurrent[entity_id],#REF!,tblClaimsCurrent[status],"UNKNOWN")) -> #REF! | E11: =_xludf.LET(t,#REF!+#REF!,IF(t=0,NA(),#REF!/t)) -> #NAME? | F11: =_xludf.LET(cnt,COUNTIFS(tblClaimsCurrent[entity_id],#REF!,tblClaimsCurrent[status],"PROMOTED"),IF(cnt=0,NA(),AVERAGEIFS(tblClaimsCurrent[confidence],tblClaimsCurrent[entity_id],#REF!,tblClaimsCurrent[status],"PROMOTED"))) -> #NAME? | G11: =_xludf.LET(cnt,COUNTIFS(tblClaimsCurrent[entity_id],#REF!,tblClaimsCurrent[field_key],"pricing_acv_mid_market",tblClaimsCurrent[status],"PROMOTED"),IF(cnt=0,NA(),SUMIFS(tblClaimsCurrent[value_num],tblClaimsCurrent[entity_id],#REF!,tblClaimsCurrent[field_key],"pricing_acv_mid_market",tblClaimsCurrent[status],"PROMOTED"))) -> #NAME? | H11: =IF(OR(NOT(ISNUMBER(#REF!)),$B$5=""),"UNKNOWN",IF(#REF!<=($B$5*0.85),"Low",IF(#REF!>=($B$5*1.15),"High","Mid"))) -> UNKNOWN | I11: =_xludf.LET(v,IFERROR(LOOKUP(2,1/((tblClaimsCurrent[entity_id]=#REF!)*(tblClaimsCurrent[field_key]="features")*(tblClaimsCurrent[status]="PROMOTED")),tblClaimsCurrent[value_text]),"UNKNOWN"),IF(v="","UNKNOWN",v)) -> #NAME? | J11: =IF(OR(#REF!="UNKNOWN",#REF!=""),NA(),1+LEN(#REF!)-LEN(SUBSTITUTE(#REF!,";",""))) -> #REF! | K11: =IF(#REF!="",NA(),IF(#REF!="SEG_MM",1,0)) -> #REF! | L11: =IF(#REF!="","",IF(COUNTIFS(tblClaimsCurrent[entity_id],#REF!,tblClaimsCurrent[field_key],"funding_round",tblClaimsCurrent[status],"PROMOTED")>0,1,0)) -> #REF! | M11: =IF(OR(#REF!=FALSE,ISNA(#REF!),ISNA(#REF!),ISNA(#REF!),#REF!="UNKNOWN"),NA(),MIN(1,Config!$B$14*MIN(1,#REF!/10)+Config!$B$15*IF(#REF!="Low",1,IF(#REF!="Mid",0.5,0))+Config!$B$16*#REF!+Config!$B$17*#REF!)) -> #REF! | N11: =IF(OR(#REF!=FALSE,ISNA(#REF!),ISNA(#REF!),ISNA(#REF!)),NA(),MIN(1,Config!$B$18*(1-MIN(1,#REF!/10))+Config!$B$19*(1-#REF!)+Config!$B$20*(1-#REF!))) -> #REF! | O11: =IF(#REF!=FALSE,"OUT_OF_SCOPE",IF(ISNA(#REF!),"UNKNOWN",IF(#REF!<Config!$B$10,"FAIL_CLOSED_LOW_COVERAGE","OK"))) -> #REF! | P11: =IFERROR(_xludf.XLOOKUP(#REF!,tblEntities[entity_id],tblEntities[segment_id]),"") | Q11: =IFERROR(_xludf.XLOOKUP(#REF!,tblEntities[entity_id],tblEntities[vertical]),"") | R11: =AND(#REF!=Dashboard!$E$2,IF(Dashboard!$E$3="All",TRUE,#REF!=Dashboard!$E$3)) -> #REF!
A12: =IF(Input!$A$11="","",Input!$A$11) -> E005 | B12: =IFERROR(_xludf.XLOOKUP(#REF!,tblEntities[entity_id],tblEntities[canonical_name]),"") | C12: =IF(#REF!="","",COUNTIFS(tblClaimsCurrent[entity_id],#REF!,tblClaimsCurrent[status],"PROMOTED")) -> #REF! | D12: =IF(#REF!="","",COUNTIFS(tblClaimsCurrent[entity_id],#REF!,tblClaimsCurrent[status],"UNKNOWN")) -> #REF! | E12: =_xludf.LET(t,#REF!+#REF!,IF(t=0,NA(),#REF!/t)) -> #NAME? | F12: =_xludf.LET(cnt,COUNTIFS(tblClaimsCurrent[entity_id],#REF!,tblClaimsCurrent[status],"PROMOTED"),IF(cnt=0,NA(),AVERAGEIFS(tblClaimsCurrent[confidence],tblClaimsCurrent[entity_id],#REF!,tblClaimsCurrent[status],"PROMOTED"))) -> #NAME? | G12: =_xludf.LET(cnt,COUNTIFS(tblClaimsCurrent[entity_id],#REF!,tblClaimsCurrent[field_key],"pricing_acv_mid_market",tblClaimsCurrent[status],"PROMOTED"),IF(cnt=0,NA(),SUMIFS(tblClaimsCurrent[value_num],tblClaimsCurrent[entity_id],#REF!,tblClaimsCurrent[field_key],"pricing_acv_mid_market",tblClaimsCurrent[status],"PROMOTED"))) -> #NAME? | H12: =IF(OR(NOT(ISNUMBER(#REF!)),$B$5=""),"UNKNOWN",IF(#REF!<=($B$5*0.85),"Low",IF(#REF!>=($B$5*1.15),"High","Mid"))) -> UNKNOWN | I12: =_xludf.LET(v,IFERROR(LOOKUP(2,1/((tblClaimsCurrent[entity_id]=#REF!)*(tblClaimsCurrent[field_key]="features")*(tblClaimsCurrent[status]="PROMOTED")),tblClaimsCurrent[value_text]),"UNKNOWN"),IF(v="","UNKNOWN",v)) -> #NAME? | J12: =IF(OR(#REF!="UNKNOWN",#REF!=""),NA(),1+LEN(#REF!)-LEN(SUBSTITUTE(#REF!,";",""))) -> #REF! | K12: =IF(#REF!="",NA(),IF(#REF!="SEG_MM",1,0)) -> #REF! | L12: =IF(#REF!="","",IF(COUNTIFS(tblClaimsCurrent[entity_id],#REF!,tblClaimsCurrent[field_key],"funding_round",tblClaimsCurrent[status],"PROMOTED")>0,1,0)) -> #REF! | M12: =IF(OR(#REF!=FALSE,ISNA(#REF!),ISNA(#REF!),ISNA(#REF!),#REF!="UNKNOWN"),NA(),MIN(1,Config!$B$14*MIN(1,#REF!/10)+Config!$B$15*IF(#REF!="Low",1,IF(#REF!="Mid",0.5,0))+Config!$B$16*#REF!+Config!$B$17*#REF!)) -> #REF! | N12: =IF(OR(#REF!=FALSE,ISNA(#REF!),ISNA(#REF!),ISNA(#REF!)),NA(),MIN(1,Config!$B$18*(1-MIN(1,#REF!/10))+Config!$B$19*(1-#REF!)+Config!$B$20*(1-#REF!))) -> #REF! | O12: =IF(#REF!=FALSE,"OUT_OF_SCOPE",IF(ISNA(#REF!),"UNKNOWN",IF(#REF!<Config!$B$10,"FAIL_CLOSED_LOW_COVERAGE","OK"))) -> #REF! | P12: =IFERROR(_xludf.XLOOKUP(#REF!,tblEntities[entity_id],tblEntities[segment_id]),"") | Q12: =IFERROR(_xludf.XLOOKUP(#REF!,tblEntities[entity_id],tblEntities[vertical]),"") | R12: =AND(#REF!=Dashboard!$E$2,IF(Dashboard!$E$3="All",TRUE,#REF!=Dashboard!$E$3)) -> #REF!
