Workbook
Name BingSearchKey: Config!$B$4
Name SerpApiKey: Config!$B$5
Name SegmentId: Dashboard!$E$2

Sheet Brand_Kit
A1: Certify Intel v1 — Excel-Only (Brand Kit)
A3: PLACEHOLDER BRANDING: Replace with official Certify Health assets (logo + hex colors).
A5: Logo (placeholder):
A12: Colors
A13: Name | B13: Hex | D13: Swatch
A14: Primary | B14: #0B2E4A
A15: Secondary | B15: #1E9FB3
A16: Accent | B16: #F2A900
A17: Background | B17: #F5F7FA
A18: Border | B18: #D0D7DE
A20: Typography
A21: Header Font | B21: Aptos Display
A22: Body Font | B22: Aptos

Sheet Config
A1: Config (Inputs in BLUE)
A3: API Keys (optional; for autonomous competitor discovery via web search APIs)
A4: Bing Search API Key | B4: ENTER_KEY
A5: SerpAPI Key | B5: ENTER_KEY
A6: Max Competitors to Import | B6: 50
A8: Refresh Settings
A9: Evidence freshness threshold (days) | B9: 30
A10: Minimum allowed known-coverage (fail closed below) | B10: 0.6
A12: Scoring Weights (editable)
A13: Weight | B13: Value
A14: Threat_FeatureOverlap | B14: 0.35
A15: Threat_PricingAggressive | B15: 0.25
A16: Threat_FundingVelocity | B16: 0.2
A17: Threat_SegmentFit | B17: 0.2
A18: Opp_FeatureGap | B18: 0.5
A19: Opp_WeakSegmentFit | B19: 0.25
A20: Opp_LowCoverage | B20: 0.25

Sheet Sources_Allowlist
A1: Sources Allowlist (Fail-Closed)
A3: Only allowlisted domains/paths can be ingested. Non-allowlisted URLs must be BLOCKED and reviewed.
A4: source_key | B4: tier | C4: domain | D4: allow_path_prefix | E4: deny_path_prefix | F4: enabled | G4: license_notes | H4: owner
A5: DEMO | B5: TIER1 | C5: file | D5: / | F5: TRUE | G5: Local demo evidence (offline) | H5: system
A6: SEC_EDGAR | B6: TIER1 | C6: www.sec.gov | D6: /Archives | E6: /cgi-bin | F6: FALSE | G6: Public filings; respect ToS/rate limits | H6: system
A7: Company_PR | B7: TIER2 | F7: FALSE | G7: Per-entity allowlist required | H7: user
A8: G2 | B8: SIGNAL | C8: www.g2.com | D8: /products | E8: / | F8: FALSE | G8: Requires license / ToS review | H8: user
A9: Capterra | B9: SIGNAL | C9: www.capterra.com | D9: / | E9: / | F9: FALSE | G9: Requires license / ToS review | H9: user

Sheet Segment_Rules
A1: Middle Market Segmentation Rules (Always Applied)
A3: Edit thresholds in BLUE. All metrics and dashboards must filter to this segment.
A4: segment_id | B4: segment_name | C4: revenue_min_usd | D4: revenue_max_usd | E4: practice_size_min | F4: practice_size_max | G4: region_includes | H4: notes
A5: SEG_MM | B5: Middle Market | C5: 5000000 | D5: 200000000 | E5: 5 | F5: 200 | G5: US (all) | H5: Placeholder thresholds; replace with Certify definition

Sheet Field_Dictionary
A1: Field Dictionary (Claim Keys + Quality Gates)
A3: Fail-closed: missing/ambiguous evidence must output UNKNOWN and create review tasks.
A4: field_key | B4: category | C4: value_type | D4: units | E4: min_confidence | F4: requires_tier1 | G4: promotion_rule | H4: example_source | I4: notes
A5: pricing_acv_mid_market | B5: Pricing | C5: number | D5: USD/year | E5: 0.8 | F5: TRUE | G5: PROMOTE_IF>=MINCONF_AND_TIER | H5: pricing page | I5: Explicit annual price or ACV
A6: arr_estimate | B6: Financial | C6: number | D6: USD/year | E6: 0.85 | F6: TRUE | G6: PROMOTE_IF_TIER1_ONLY | H6: 10-K/press | I6: Only explicit ARR mention
A7: contract_terms | B7: Pricing | C7: text | E7: 0.7 | F7: FALSE | G7: PROMOTE_IF>=MINCONF | H7: pricing/terms | I7: Explicit contract duration/cancellation
A8: features | B8: Product | C8: text | E8: 0.65 | F8: FALSE | G8: PROMOTE_IF>=MINCONF | H8: product page | I8: Semicolon-separated feature tags
A9: funding_round | B9: Funding | C9: text | E9: 0.8 | F9: TRUE | G9: PROMOTE_IF_TIER1_ONLY | H9: filings/press | I9: Explicit round amount and date
A10: geo_coverage | B10: Market | C10: text | E10: 0.7 | F10: FALSE | G10: PROMOTE_IF>=MINCONF | H10: about page | I10: Regions served
A11: practice_size_target | B11: Market | C11: text | E11: 0.7 | F11: FALSE | G11: PROMOTE_IF>=MINCONF | H11: case studies | I11: Explicit ICP statements

Sheet Feature_Taxonomy
A1: Feature Taxonomy (canonical features + synonyms)
A4: feature_id | B4: feature_name | C4: category | D4: synonyms_csv | E4: notes
A5: F001 | B5: Eligibility Verification | C5: Revenue Cycle | D5: eligibility check;insurance eligibility
A6: F002 | B6: Prior Authorization | C6: Revenue Cycle | D6: prior auth;pre-authorization
A7: F003 | B7: Patient Payments | C7: Billing | D7: payment portal;online payments
A8: F004 | B8: Scheduling | C8: Front Office | D8: appointment scheduling;calendar

Sheet Input
A1: Input (Normalized; Evidence-Led)
A2: Green = imported/linked; Blue = editable inputs; Yellow/Red = review required.
A4: Entities
A6: entity_id | B6: canonical_name | C6: domain | D6: vertical | E6: region | F6: segment_id | G6: discovered_via | H6: discovered_at | I6: status | J6: hq_city | K6: hq_state | L6: notes
A7: E001 | B7: AcmeRival | C7: acmerival.com | D7: Provider Credentialing | E7: US | F7: SEG_MM | G7: DEMO | H7: 2026-01-12 | I7: ACTIVE | J7: New York | K7: NY | L7: DEMO ROW
A8: E002 | B8: EnrollPro | C8: enrollpro.io | D8: Provider Enrollment | E8: US | F8: SEG_MM | G8: DEMO | H8: 2026-01-12 | I8: ACTIVE | J8: Austin | K8: TX | L8: DEMO ROW
A9: E003 | B9: ComplianceFlow | C9: complianceflow.health | D9: Compliance Automation | E9: US | F9: SEG_MM | G9: DEMO | H9: 2026-01-12 | I9: ACTIVE | J9: Chicago | K9: IL | L9: DEMO ROW
A10: E004 | B10: CredentiSure | C10: credentisure.com | D10: Credentialing | E10: US | F10: SEG_MM | G10: DEMO | H10: 2026-01-12 | I10: ACTIVE | J10: Boston | K10: MA | L10: DEMO ROW
A11: E005 | B11: PracticeOps | C11: practiceops.com | D11: Practice Ops Suite | E11: US | F11: SEG_MM | G11: DEMO | H11: 2026-01-12 | I11: ACTIVE | J11: Miami | K11: FL | L11: DEMO ROW
A12: E006 | B12: MidMarketMedTech | C12: mmmedtech.com | D12: Healthcare IT | E12: US | F12: SEG_MM | G12: DEMO | H12: 2026-01-12 | I12: ACTIVE | J12: Seattle | K12: WA | L12: DEMO ROW
A15: Evidence (Claims must link here)
A17: evidence_id | B17: entity_id | C17: source_key | D17: tier | E17: url | F17: fetched_at | G17: snippet | H17: content_hash | I17: text_hash | J17: domain_calc | K17: allowlist_ok
A18: EV001 | B18: E001 | C18: DEMO | D18: TIER1 | E18: file://docs/demo_sources/E001_pricing.html | F18: 2026-01-12 | G18: DEMO evidence placeholder. Replace with allowlisted URL + snippet. | H18: 0217e879a9ae84b4 | I18: 46aae5c96408e7ec | J18: =IF(LEFT([@url],7)="file://","file",LOWER(TEXTBEFORE(TEXTAFTER([@url],"//"),"/"))) | K18: =LET(sk,[@source_key],en,IFERROR(XLOOKUP(sk,tblSourcesAllowlist[source_key],tblSourcesAllowlist[enabled]),"FALSE"),dom,[@domain_calc],domOK,IF(dom="file",TRUE,ISNUMBER(MATCH(dom,FILTER(tblSourcesAllowlist[domain],tblSourcesAllowlist[enabled]="TRUE"),0))),AND(en="TRUE",domOK))
A19: EV002 | B19: E002 | C19: DEMO | D19: TIER1 | E19: file://docs/demo_sources/E002_pricing.html | F19: 2026-01-12 | G19: DEMO evidence placeholder. Replace with allowlisted URL + snippet. | H19: 3deb1e85e3854868 | I19: 46aae5c96408e7ec | J19: =IF(LEFT([@url],7)="file://","file",LOWER(TEXTBEFORE(TEXTAFTER([@url],"//"),"/"))) | K19: =LET(sk,[@source_key],en,IFERROR(XLOOKUP(sk,tblSourcesAllowlist[source_key],tblSourcesAllowlist[enabled]),"FALSE"),dom,[@domain_calc],domOK,IF(dom="file",TRUE,ISNUMBER(MATCH(dom,FILTER(tblSourcesAllowlist[domain],tblSourcesAllowlist[enabled]="TRUE"),0))),AND(en="TRUE",domOK))
A20: EV003 | B20: E003 | C20: DEMO | D20: TIER1 | E20: file://docs/demo_sources/E003_pricing.html | F20: 2026-01-12 | G20: DEMO evidence placeholder. Replace with allowlisted URL + snippet. | H20: d42285f8d1a9736f | I20: 46aae5c96408e7ec | J20: =IF(LEFT([@url],7)="file://","file",LOWER(TEXTBEFORE(TEXTAFTER([@url],"//"),"/"))) | K20: =LET(sk,[@source_key],en,IFERROR(XLOOKUP(sk,tblSourcesAllowlist[source_key],tblSourcesAllowlist[enabled]),"FALSE"),dom,[@domain_calc],domOK,IF(dom="file",TRUE,ISNUMBER(MATCH(dom,FILTER(tblSourcesAllowlist[domain],tblSourcesAllowlist[enabled]="TRUE"),0))),AND(en="TRUE",domOK))
A21: EV004 | B21: E004 | C21: DEMO | D21: TIER1 | E21: file://docs/demo_sources/E004_pricing.html | F21: 2026-01-12 | G21: DEMO evidence placeholder. Replace with allowlisted URL + snippet. | H21: b1e3c58050111249 | I21: 46aae5c96408e7ec | J21: =IF(LEFT([@url],7)="file://","file",LOWER(TEXTBEFORE(TEXTAFTER([@url],"//"),"/"))) | K21: =LET(sk,[@source_key],en,IFERROR(XLOOKUP(sk,tblSourcesAllowlist[source_key],tblSourcesAllowlist[enabled]),"FALSE"),dom,[@domain_calc],domOK,IF(dom="file",TRUE,ISNUMBER(MATCH(dom,FILTER(tblSourcesAllowlist[domain],tblSourcesAllowlist[enabled]="TRUE"),0))),AND(en="TRUE",domOK))
A22: EV005 | B22: E001 | C22: DEMO | D22: SIGNAL | E22: file://docs/demo_sources/E001_pr.html | F22: 2026-01-12 | G22: DEMO PR mention (signal only). | H22: 0510eddd78110203 | I22: 41bfa2f2111d7821 | J22: =IF(LEFT([@url],7)="file://","file",LOWER(TEXTBEFORE(TEXTAFTER([@url],"//"),"/"))) | K22: =LET(sk,[@source_key],en,IFERROR(XLOOKUP(sk,tblSourcesAllowlist[source_key],tblSourcesAllowlist[enabled]),"FALSE"),dom,[@domain_calc],domOK,IF(dom="file",TRUE,ISNUMBER(MATCH(dom,FILTER(tblSourcesAllowlist[domain],tblSourcesAllowlist[enabled]="TRUE"),0))),AND(en="TRUE",domOK))
A25: Claim Candidates (Fail-Closed; UNKNOWN → Review)
A27: candidate_id | B27: entity_id | C27: segment_id | D27: field_key | E27: value_text | F27: value_num | G27: units | H27: confidence | I27: evidence_id | J27: span_start | K27: span_end | L27: tier | M27: status_final | N27: status_manual | O27: status_auto | P27: auto_reason | Q27: reviewer_notes
A28: C001 | B28: E001 | C28: SEG_MM | D28: pricing_acv_mid_market | F28: 12000 | G28: USD/year | H28: 0.9 | I28: EV001 | J28: 0 | K28: 200 | L28: TIER1 | M28: =LET(man,[@status_manual],auto,[@status_auto],IF(man="REJECTED","REJECTED",IF(man="IN_REVIEW","IN_REVIEW",IF(man="PROMOTED",IF(auto="PROMOTABLE","PROMOTED","REVIEW_REQUIRED"),IF(auto="PROMOTABLE","PROMOTED","REVIEW_REQUIRED"))))) | N28: PROMOTED | O28: =LET(minc,IFERROR(XLOOKUP([@field_key],tblFieldDictionary[field_key],tblFieldDictionary[min_confidence]),1),req1,IFERROR(XLOOKUP([@field_key],tblFieldDictionary[field_key],tblFieldDictionary[requires_tier1]),"FALSE"),hasEvid,ISNUMBER(MATCH([@evidence_id],tblEvidence[evidence_id],0)),hasVal,OR(AND([@value_text]<>"",[@value_text]<>"UNKNOWN"),[@value_num]<>""),confOK,[@confidence]>=minc,tierOK,IF(req1="TRUE",[@tier]="TIER1",TRUE),IF(NOT(hasEvid),"REVIEW_REQUIRED",IF(NOT(hasVal),"REVIEW_REQUIRED",IF(NOT(confOK),"REVIEW_REQUIRED",IF(NOT(tierOK),"REVIEW_REQUIRED","PROMOTABLE"))))) | P28: =LET(minc,IFERROR(XLOOKUP([@field_key],tblFieldDictionary[field_key],tblFieldDictionary[min_confidence]),1),req1,IFERROR(XLOOKUP([@field_key],tblFieldDictionary[field_key],tblFieldDictionary[requires_tier1]),"FALSE"),hasEvid,ISNUMBER(MATCH([@evidence_id],tblEvidence[evidence_id],0)),hasVal,OR(AND([@value_text]<>"",[@value_text]<>"UNKNOWN"),[@value_num]<>""),confOK,[@confidence]>=minc,tierOK,IF(req1="TRUE",[@tier]="TIER1",TRUE),IF(NOT(hasEvid),"MISSING_EVIDENCE",IF(NOT(hasVal),"MISSING_VALUE",IF(NOT(confOK),"LOW_CONFIDENCE",IF(NOT(tierOK),"TIER1_REQUIRED","OK")))))
A29: C002 | B29: E001 | C29: SEG_MM | D29: contract_terms | E29: Annual contract, cancel with 30 days notice | H29: 0.75 | I29: EV001 | J29: 201 | K29: 320 | L29: TIER1 | M29: =LET(man,[@status_manual],auto,[@status_auto],IF(man="REJECTED","REJECTED",IF(man="IN_REVIEW","IN_REVIEW",IF(man="PROMOTED",IF(auto="PROMOTABLE","PROMOTED","REVIEW_REQUIRED"),IF(auto="PROMOTABLE","PROMOTED","REVIEW_REQUIRED"))))) | N29: PROMOTED | O29: =LET(minc,IFERROR(XLOOKUP([@field_key],tblFieldDictionary[field_key],tblFieldDictionary[min_confidence]),1),req1,IFERROR(XLOOKUP([@field_key],tblFieldDictionary[field_key],tblFieldDictionary[requires_tier1]),"FALSE"),hasEvid,ISNUMBER(MATCH([@evidence_id],tblEvidence[evidence_id],0)),hasVal,OR(AND([@value_text]<>"",[@value_text]<>"UNKNOWN"),[@value_num]<>""),confOK,[@confidence]>=minc,tierOK,IF(req1="TRUE",[@tier]="TIER1",TRUE),IF(NOT(hasEvid),"REVIEW_REQUIRED",IF(NOT(hasVal),"REVIEW_REQUIRED",IF(NOT(confOK),"REVIEW_REQUIRED",IF(NOT(tierOK),"REVIEW_REQUIRED","PROMOTABLE"))))) | P29: =LET(minc,IFERROR(XLOOKUP([@field_key],tblFieldDictionary[field_key],tblFieldDictionary[min_confidence]),1),req1,IFERROR(XLOOKUP([@field_key],tblFieldDictionary[field_key],tblFieldDictionary[requires_tier1]),"FALSE"),hasEvid,ISNUMBER(MATCH([@evidence_id],tblEvidence[evidence_id],0)),hasVal,OR(AND([@value_text]<>"",[@value_text]<>"UNKNOWN"),[@value_num]<>""),confOK,[@confidence]>=minc,tierOK,IF(req1="TRUE",[@tier]="TIER1",TRUE),IF(NOT(hasEvid),"MISSING_EVIDENCE",IF(NOT(hasVal),"MISSING_VALUE",IF(NOT(confOK),"LOW_CONFIDENCE",IF(NOT(tierOK),"TIER1_REQUIRED","OK")))))
A30: C003 | B30: E001 | C30: SEG_MM | D30: features | E30: Credentialing; Enrollment; Payer Roster | H30: 0.7 | I30: EV001 | J30: 321 | K30: 520 | L30: TIER1 | M30: =LET(man,[@status_manual],auto,[@status_auto],IF(man="REJECTED","REJECTED",IF(man="IN_REVIEW","IN_REVIEW",IF(man="PROMOTED",IF(auto="PROMOTABLE","PROMOTED","REVIEW_REQUIRED"),IF(auto="PROMOTABLE","PROMOTED","REVIEW_REQUIRED"))))) | N30: PROMOTED | O30: =LET(minc,IFERROR(XLOOKUP([@field_key],tblFieldDictionary[field_key],tblFieldDictionary[min_confidence]),1),req1,IFERROR(XLOOKUP([@field_key],tblFieldDictionary[field_key],tblFieldDictionary[requires_tier1]),"FALSE"),hasEvid,ISNUMBER(MATCH([@evidence_id],tblEvidence[evidence_id],0)),hasVal,OR(AND([@value_text]<>"",[@value_text]<>"UNKNOWN"),[@value_num]<>""),confOK,[@confidence]>=minc,tierOK,IF(req1="TRUE",[@tier]="TIER1",TRUE),IF(NOT(hasEvid),"REVIEW_REQUIRED",IF(NOT(hasVal),"REVIEW_REQUIRED",IF(NOT(confOK),"REVIEW_REQUIRED",IF(NOT(tierOK),"REVIEW_REQUIRED","PROMOTABLE"))))) | P30: =LET(minc,IFERROR(XLOOKUP([@field_key],tblFieldDictionary[field_key],tblFieldDictionary[min_confidence]),1),req1,IFERROR(XLOOKUP([@field_key],tblFieldDictionary[field_key],tblFieldDictionary[requires_tier1]),"FALSE"),hasEvid,ISNUMBER(MATCH([@evidence_id],tblEvidence[evidence_id],0)),hasVal,OR(AND([@value_text]<>"",[@value_text]<>"UNKNOWN"),[@value_num]<>""),confOK,[@confidence]>=minc,tierOK,IF(req1="TRUE",[@tier]="TIER1",TRUE),IF(NOT(hasEvid),"MISSING_EVIDENCE",IF(NOT(hasVal),"MISSING_VALUE",IF(NOT(confOK),"LOW_CONFIDENCE",IF(NOT(tierOK),"TIER1_REQUIRED","OK")))))
A31: C004 | B31: E002 | C31: SEG_MM | D31: pricing_acv_mid_market | E31: UNKNOWN | G31: USD/year | H31: 0.2 | I31: EV002 | J31: 0 | K31: 180 | L31: TIER1 | M31: =LET(man,[@status_manual],auto,[@status_auto],IF(man="REJECTED","REJECTED",IF(man="IN_REVIEW","IN_REVIEW",IF(man="PROMOTED",IF(auto="PROMOTABLE","PROMOTED","REVIEW_REQUIRED"),IF(auto="PROMOTABLE","PROMOTED","REVIEW_REQUIRED"))))) | N31: REVIEW_REQUIRED | O31: =LET(minc,IFERROR(XLOOKUP([@field_key],tblFieldDictionary[field_key],tblFieldDictionary[min_confidence]),1),req1,IFERROR(XLOOKUP([@field_key],tblFieldDictionary[field_key],tblFieldDictionary[requires_tier1]),"FALSE"),hasEvid,ISNUMBER(MATCH([@evidence_id],tblEvidence[evidence_id],0)),hasVal,OR(AND([@value_text]<>"",[@value_text]<>"UNKNOWN"),[@value_num]<>""),confOK,[@confidence]>=minc,tierOK,IF(req1="TRUE",[@tier]="TIER1",TRUE),IF(NOT(hasEvid),"REVIEW_REQUIRED",IF(NOT(hasVal),"REVIEW_REQUIRED",IF(NOT(confOK),"REVIEW_REQUIRED",IF(NOT(tierOK),"REVIEW_REQUIRED","PROMOTABLE"))))) | P31: =LET(minc,IFERROR(XLOOKUP([@field_key],tblFieldDictionary[field_key],tblFieldDictionary[min_confidence]),1),req1,IFERROR(XLOOKUP([@field_key],tblFieldDictionary[field_key],tblFieldDictionary[requires_tier1]),"FALSE"),hasEvid,ISNUMBER(MATCH([@evidence_id],tblEvidence[evidence_id],0)),hasVal,OR(AND([@value_text]<>"",[@value_text]<>"UNKNOWN"),[@value_num]<>""),confOK,[@confidence]>=minc,tierOK,IF(req1="TRUE",[@tier]="TIER1",TRUE),IF(NOT(hasEvid),"MISSING_EVIDENCE",IF(NOT(hasVal),"MISSING_VALUE",IF(NOT(confOK),"LOW_CONFIDENCE",IF(NOT(tierOK),"TIER1_REQUIRED","OK"))))) | Q31: No explicit ACV on page
A32: C005 | B32: E002 | C32: SEG_MM | D32: features | E32: Enrollment; Automated forms; Integrations | H32: 0.7 | I32: EV002 | J32: 181 | K32: 420 | L32: TIER1 | M32: =LET(man,[@status_manual],auto,[@status_auto],IF(man="REJECTED","REJECTED",IF(man="IN_REVIEW","IN_REVIEW",IF(man="PROMOTED",IF(auto="PROMOTABLE","PROMOTED","REVIEW_REQUIRED"),IF(auto="PROMOTABLE","PROMOTED","REVIEW_REQUIRED"))))) | N32: PROMOTED | O32: =LET(minc,IFERROR(XLOOKUP([@field_key],tblFieldDictionary[field_key],tblFieldDictionary[min_confidence]),1),req1,IFERROR(XLOOKUP([@field_key],tblFieldDictionary[field_key],tblFieldDictionary[requires_tier1]),"FALSE"),hasEvid,ISNUMBER(MATCH([@evidence_id],tblEvidence[evidence_id],0)),hasVal,OR(AND([@value_text]<>"",[@value_text]<>"UNKNOWN"),[@value_num]<>""),confOK,[@confidence]>=minc,tierOK,IF(req1="TRUE",[@tier]="TIER1",TRUE),IF(NOT(hasEvid),"REVIEW_REQUIRED",IF(NOT(hasVal),"REVIEW_REQUIRED",IF(NOT(confOK),"REVIEW_REQUIRED",IF(NOT(tierOK),"REVIEW_REQUIRED","PROMOTABLE"))))) | P32: =LET(minc,IFERROR(XLOOKUP([@field_key],tblFieldDictionary[field_key],tblFieldDictionary[min_confidence]),1),req1,IFERROR(XLOOKUP([@field_key],tblFieldDictionary[field_key],tblFieldDictionary[requires_tier1]),"FALSE"),hasEvid,ISNUMBER(MATCH([@evidence_id],tblEvidence[evidence_id],0)),hasVal,OR(AND([@value_text]<>"",[@value_text]<>"UNKNOWN"),[@value_num]<>""),confOK,[@confidence]>=minc,tierOK,IF(req1="TRUE",[@tier]="TIER1",TRUE),IF(NOT(hasEvid),"MISSING_EVIDENCE",IF(NOT(hasVal),"MISSING_VALUE",IF(NOT(confOK),"LOW_CONFIDENCE",IF(NOT(tierOK),"TIER1_REQUIRED","OK")))))
A33: C006 | B33: E003 | C33: SEG_MM | D33: funding_round | E33: UNKNOWN | H33: 0.1 | I33: EV003 | J33: 0 | K33: 250 | L33: SIGNAL | M33: =LET(man,[@status_manual],auto,[@status_auto],IF(man="REJECTED","REJECTED",IF(man="IN_REVIEW","IN_REVIEW",IF(man="PROMOTED",IF(auto="PROMOTABLE","PROMOTED","REVIEW_REQUIRED"),IF(auto="PROMOTABLE","PROMOTED","REVIEW_REQUIRED"))))) | N33: REVIEW_REQUIRED | O33: =LET(minc,IFERROR(XLOOKUP([@field_key],tblFieldDictionary[field_key],tblFieldDictionary[min_confidence]),1),req1,IFERROR(XLOOKUP([@field_key],tblFieldDictionary[field_key],tblFieldDictionary[requires_tier1]),"FALSE"),hasEvid,ISNUMBER(MATCH([@evidence_id],tblEvidence[evidence_id],0)),hasVal,OR(AND([@value_text]<>"",[@value_text]<>"UNKNOWN"),[@value_num]<>""),confOK,[@confidence]>=minc,tierOK,IF(req1="TRUE",[@tier]="TIER1",TRUE),IF(NOT(hasEvid),"REVIEW_REQUIRED",IF(NOT(hasVal),"REVIEW_REQUIRED",IF(NOT(confOK),"REVIEW_REQUIRED",IF(NOT(tierOK),"REVIEW_REQUIRED","PROMOTABLE"))))) | P33: =LET(minc,IFERROR(XLOOKUP([@field_key],tblFieldDictionary[field_key],tblFieldDictionary[min_confidence]),1),req1,IFERROR(XLOOKUP([@field_key],tblFieldDictionary[field_key],tblFieldDictionary[requires_tier1]),"FALSE"),hasEvid,ISNUMBER(MATCH([@evidence_id],tblEvidence[evidence_id],0)),hasVal,OR(AND([@value_text]<>"",[@value_text]<>"UNKNOWN"),[@value_num]<>""),confOK,[@confidence]>=minc,tierOK,IF(req1="TRUE",[@tier]="TIER1",TRUE),IF(NOT(hasEvid),"MISSING_EVIDENCE",IF(NOT(hasVal),"MISSING_VALUE",IF(NOT(confOK),"LOW_CONFIDENCE",IF(NOT(tierOK),"TIER1_REQUIRED","OK"))))) | Q33: Signal only; needs tier-1 corroboration
A34: C007 | B34: E004 | C34: SEG_MM | D34: pricing_acv_mid_market | F34: 18000 | G34: USD/year | H34: 0.82 | I34: EV004 | J34: 0 | K34: 210 | L34: TIER1 | M34: =LET(man,[@status_manual],auto,[@status_auto],IF(man="REJECTED","REJECTED",IF(man="IN_REVIEW","IN_REVIEW",IF(man="PROMOTED",IF(auto="PROMOTABLE","PROMOTED","REVIEW_REQUIRED"),IF(auto="PROMOTABLE","PROMOTED","REVIEW_REQUIRED"))))) | N34: PROMOTED | O34: =LET(minc,IFERROR(XLOOKUP([@field_key],tblFieldDictionary[field_key],tblFieldDictionary[min_confidence]),1),req1,IFERROR(XLOOKUP([@field_key],tblFieldDictionary[field_key],tblFieldDictionary[requires_tier1]),"FALSE"),hasEvid,ISNUMBER(MATCH([@evidence_id],tblEvidence[evidence_id],0)),hasVal,OR(AND([@value_text]<>"",[@value_text]<>"UNKNOWN"),[@value_num]<>""),confOK,[@confidence]>=minc,tierOK,IF(req1="TRUE",[@tier]="TIER1",TRUE),IF(NOT(hasEvid),"REVIEW_REQUIRED",IF(NOT(hasVal),"REVIEW_REQUIRED",IF(NOT(confOK),"REVIEW_REQUIRED",IF(NOT(tierOK),"REVIEW_REQUIRED","PROMOTABLE"))))) | P34: =LET(minc,IFERROR(XLOOKUP([@field_key],tblFieldDictionary[field_key],tblFieldDictionary[min_confidence]),1),req1,IFERROR(XLOOKUP([@field_key],tblFieldDictionary[field_key],tblFieldDictionary[requires_tier1]),"FALSE"),hasEvid,ISNUMBER(MATCH([@evidence_id],tblEvidence[evidence_id],0)),hasVal,OR(AND([@value_text]<>"",[@value_text]<>"UNKNOWN"),[@value_num]<>""),confOK,[@confidence]>=minc,tierOK,IF(req1="TRUE",[@tier]="TIER1",TRUE),IF(NOT(hasEvid),"MISSING_EVIDENCE",IF(NOT(hasVal),"MISSING_VALUE",IF(NOT(confOK),"LOW_CONFIDENCE",IF(NOT(tierOK),"TIER1_REQUIRED","OK")))))
A35: C008 | B35: E004 | C35: SEG_MM | D35: features | E35: Credentialing; Compliance; Analytics | H35: 0.68 | I35: EV004 | J35: 211 | K35: 400 | L35: TIER1 | M35: =LET(man,[@status_manual],auto,[@status_auto],IF(man="REJECTED","REJECTED",IF(man="IN_REVIEW","IN_REVIEW",IF(man="PROMOTED",IF(auto="PROMOTABLE","PROMOTED","REVIEW_REQUIRED"),IF(auto="PROMOTABLE","PROMOTED","REVIEW_REQUIRED"))))) | N35: PROMOTED | O35: =LET(minc,IFERROR(XLOOKUP([@field_key],tblFieldDictionary[field_key],tblFieldDictionary[min_confidence]),1),req1,IFERROR(XLOOKUP([@field_key],tblFieldDictionary[field_key],tblFieldDictionary[requires_tier1]),"FALSE"),hasEvid,ISNUMBER(MATCH([@evidence_id],tblEvidence[evidence_id],0)),hasVal,OR(AND([@value_text]<>"",[@value_text]<>"UNKNOWN"),[@value_num]<>""),confOK,[@confidence]>=minc,tierOK,IF(req1="TRUE",[@tier]="TIER1",TRUE),IF(NOT(hasEvid),"REVIEW_REQUIRED",IF(NOT(hasVal),"REVIEW_REQUIRED",IF(NOT(confOK),"REVIEW_REQUIRED",IF(NOT(tierOK),"REVIEW_REQUIRED","PROMOTABLE"))))) | P35: =LET(minc,IFERROR(XLOOKUP([@field_key],tblFieldDictionary[field_key],tblFieldDictionary[min_confidence]),1),req1,IFERROR(XLOOKUP([@field_key],tblFieldDictionary[field_key],tblFieldDictionary[requires_tier1]),"FALSE"),hasEvid,ISNUMBER(MATCH([@evidence_id],tblEvidence[evidence_id],0)),hasVal,OR(AND([@value_text]<>"",[@value_text]<>"UNKNOWN"),[@value_num]<>""),confOK,[@confidence]>=minc,tierOK,IF(req1="TRUE",[@tier]="TIER1",TRUE),IF(NOT(hasEvid),"MISSING_EVIDENCE",IF(NOT(hasVal),"MISSING_VALUE",IF(NOT(confOK),"LOW_CONFIDENCE",IF(NOT(tierOK),"TIER1_REQUIRED","OK")))))
A36: C009 | B36: E005 | C36: SEG_MM | D36: pricing_acv_mid_market | F36: 9000 | G36: USD/year | H36: 0.8 | I36: EV005 | J36: 0 | K36: 200 | L36: SIGNAL | M36: =LET(man,[@status_manual],auto,[@status_auto],IF(man="REJECTED","REJECTED",IF(man="IN_REVIEW","IN_REVIEW",IF(man="PROMOTED",IF(auto="PROMOTABLE","PROMOTED","REVIEW_REQUIRED"),IF(auto="PROMOTABLE","PROMOTED","REVIEW_REQUIRED"))))) | N36: REVIEW_REQUIRED | O36: =LET(minc,IFERROR(XLOOKUP([@field_key],tblFieldDictionary[field_key],tblFieldDictionary[min_confidence]),1),req1,IFERROR(XLOOKUP([@field_key],tblFieldDictionary[field_key],tblFieldDictionary[requires_tier1]),"FALSE"),hasEvid,ISNUMBER(MATCH([@evidence_id],tblEvidence[evidence_id],0)),hasVal,OR(AND([@value_text]<>"",[@value_text]<>"UNKNOWN"),[@value_num]<>""),confOK,[@confidence]>=minc,tierOK,IF(req1="TRUE",[@tier]="TIER1",TRUE),IF(NOT(hasEvid),"REVIEW_REQUIRED",IF(NOT(hasVal),"REVIEW_REQUIRED",IF(NOT(confOK),"REVIEW_REQUIRED",IF(NOT(tierOK),"REVIEW_REQUIRED","PROMOTABLE"))))) | P36: =LET(minc,IFERROR(XLOOKUP([@field_key],tblFieldDictionary[field_key],tblFieldDictionary[min_confidence]),1),req1,IFERROR(XLOOKUP([@field_key],tblFieldDictionary[field_key],tblFieldDictionary[requires_tier1]),"FALSE"),hasEvid,ISNUMBER(MATCH([@evidence_id],tblEvidence[evidence_id],0)),hasVal,OR(AND([@value_text]<>"",[@value_text]<>"UNKNOWN"),[@value_num]<>""),confOK,[@confidence]>=minc,tierOK,IF(req1="TRUE",[@tier]="TIER1",TRUE),IF(NOT(hasEvid),"MISSING_EVIDENCE",IF(NOT(hasVal),"MISSING_VALUE",IF(NOT(confOK),"LOW_CONFIDENCE",IF(NOT(tierOK),"TIER1_REQUIRED","OK"))))) | Q36: Pricing from signal source; needs tier-1

Sheet Claims_Current
A1: Claims_Current (Normalized Claims; Versioned via Review Workflow)
A2: This sheet is the contract consumed by Metrics and Dashboards. Values must be evidence-backed; missing/uncertain → UNKNOWN.
A4: entity_id | B4: canonical_name | C4: segment_id | D4: field_key | E4: value_text | F4: value_num | G4: units | H4: confidence | I4: evidence_id | J4: evidence_url | K4: tier | L4: status | M4: last_updated | N4: explain
A5: E001 | B5: AcmeRival | C5: SEG_MM | D5: pricing_acv_mid_market | E5: =LET(v,IFERROR(LOOKUP(2,1/((tblClaimCandidates[entity_id]=[@entity_id])*(tblClaimCandidates[field_key]=[@field_key])*(tblClaimCandidates[status_final]="PROMOTED")),tblClaimCandidates[value_text]),""),IF(v="","UNKNOWN",v)) | F5: =LET(cnt,COUNTIFS(tblClaimCandidates[entity_id],[@entity_id],tblClaimCandidates[field_key],[@field_key],tblClaimCandidates[status_final],"PROMOTED"),IF(cnt=0,NA(),SUMIFS(tblClaimCandidates[value_num],tblClaimCandidates[entity_id],[@entity_id],tblClaimCandidates[field_key],[@field_key],tblClaimCandidates[status_final],"PROMOTED"))) | G5: =IFERROR(XLOOKUP([@field_key],tblFieldDictionary[field_key],tblFieldDictionary[units]),"") | H5: =LET(cnt,COUNTIFS(tblClaimCandidates[entity_id],[@entity_id],tblClaimCandidates[field_key],[@field_key],tblClaimCandidates[status_final],"PROMOTED"),IF(cnt=0,NA(),AVERAGEIFS(tblClaimCandidates[confidence],tblClaimCandidates[entity_id],[@entity_id],tblClaimCandidates[field_key],[@field_key],tblClaimCandidates[status_final],"PROMOTED"))) | I5: =IFERROR(LOOKUP(2,1/((tblClaimCandidates[entity_id]=[@entity_id])*(tblClaimCandidates[field_key]=[@field_key])*(tblClaimCandidates[status_final]="PROMOTED")),tblClaimCandidates[evidence_id]),"") | J5: =IF([@evidence_id]="","",IFERROR(XLOOKUP([@evidence_id],tblEvidence[evidence_id],tblEvidence[url],""),"")) | K5: =IFERROR(LOOKUP(2,1/((tblClaimCandidates[entity_id]=[@entity_id])*(tblClaimCandidates[field_key]=[@field_key])*(tblClaimCandidates[status_final]="PROMOTED")),tblClaimCandidates[tier]),"") | L5: =IF([@value_text]="UNKNOWN","UNKNOWN","PROMOTED") | M5: =IF([@status]="PROMOTED",TODAY(),"") | N5: =IF([@status]="PROMOTED","evidence_linked","UNKNOWN_or_unverified")
A6: E001 | B6: AcmeRival | C6: SEG_MM | D6: arr_estimate | E6: =LET(v,IFERROR(LOOKUP(2,1/((tblClaimCandidates[entity_id]=[@entity_id])*(tblClaimCandidates[field_key]=[@field_key])*(tblClaimCandidates[status_final]="PROMOTED")),tblClaimCandidates[value_text]),""),IF(v="","UNKNOWN",v)) | F6: =LET(cnt,COUNTIFS(tblClaimCandidates[entity_id],[@entity_id],tblClaimCandidates[field_key],[@field_key],tblClaimCandidates[status_final],"PROMOTED"),IF(cnt=0,NA(),SUMIFS(tblClaimCandidates[value_num],tblClaimCandidates[entity_id],[@entity_id],tblClaimCandidates[field_key],[@field_key],tblClaimCandidates[status_final],"PROMOTED"))) | G6: =IFERROR(XLOOKUP([@field_key],tblFieldDictionary[field_key],tblFieldDictionary[units]),"") | H6: =LET(cnt,COUNTIFS(tblClaimCandidates[entity_id],[@entity_id],tblClaimCandidates[field_key],[@field_key],tblClaimCandidates[status_final],"PROMOTED"),IF(cnt=0,NA(),AVERAGEIFS(tblClaimCandidates[confidence],tblClaimCandidates[entity_id],[@entity_id],tblClaimCandidates[field_key],[@field_key],tblClaimCandidates[status_final],"PROMOTED"))) | I6: =IFERROR(LOOKUP(2,1/((tblClaimCandidates[entity_id]=[@entity_id])*(tblClaimCandidates[field_key]=[@field_key])*(tblClaimCandidates[status_final]="PROMOTED")),tblClaimCandidates[evidence_id]),"") | J6: =IF([@evidence_id]="","",IFERROR(XLOOKUP([@evidence_id],tblEvidence[evidence_id],tblEvidence[url],""),"")) | K6: =IFERROR(LOOKUP(2,1/((tblClaimCandidates[entity_id]=[@entity_id])*(tblClaimCandidates[field_key]=[@field_key])*(tblClaimCandidates[status_final]="PROMOTED")),tblClaimCandidates[tier]),"") | L6: =IF([@value_text]="UNKNOWN","UNKNOWN","PROMOTED") | M6: =IF([@status]="PROMOTED",TODAY(),"") | N6: =IF([@status]="PROMOTED","evidence_linked","UNKNOWN_or_unverified")
A7: E001 | B7: AcmeRival | C7: SEG_MM | D7: contract_terms | E7: =LET(v,IFERROR(LOOKUP(2,1/((tblClaimCandidates[entity_id]=[@entity_id])*(tblClaimCandidates[field_key]=[@field_key])*(tblClaimCandidates[status_final]="PROMOTED")),tblClaimCandidates[value_text]),""),IF(v="","UNKNOWN",v)) | F7: =LET(cnt,COUNTIFS(tblClaimCandidates[entity_id],[@entity_id],tblClaimCandidates[field_key],[@field_key],tblClaimCandidates[status_final],"PROMOTED"),IF(cnt=0,NA(),SUMIFS(tblClaimCandidates[value_num],tblClaimCandidates[entity_id],[@entity_id],tblClaimCandidates[field_key],[@field_key],tblClaimCandidates[status_final],"PROMOTED"))) | G7: =IFERROR(XLOOKUP([@field_key],tblFieldDictionary[field_key],tblFieldDictionary[units]),"") | H7: =LET(cnt,COUNTIFS(tblClaimCandidates[entity_id],[@entity_id],tblClaimCandidates[field_key],[@field_key],tblClaimCandidates[status_final],"PROMOTED"),IF(cnt=0,NA(),AVERAGEIFS(tblClaimCandidates[confidence],tblClaimCandidates[entity_id],[@entity_id],tblClaimCandidates[field_key],[@field_key],tblClaimCandidates[status_final],"PROMOTED"))) | I7: =IFERROR(LOOKUP(2,1/((tblClaimCandidates[entity_id]=[@entity_id])*(tblClaimCandidates[field_key]=[@field_key])*(tblClaimCandidates[status_final]="PROMOTED")),tblClaimCandidates[evidence_id]),"") | J7: =IF([@evidence_id]="","",IFERROR(XLOOKUP([@evidence_id],tblEvidence[evidence_id],tblEvidence[url],""),"")) | K7: =IFERROR(LOOKUP(2,1/((tblClaimCandidates[entity_id]=[@entity_id])*(tblClaimCandidates[field_key]=[@field_key])*(tblClaimCandidates[status_final]="PROMOTED")),tblClaimCandidates[tier]),"") | L7: =IF([@value_text]="UNKNOWN","UNKNOWN","PROMOTED") | M7: =IF([@status]="PROMOTED",TODAY(),"") | N7: =IF([@status]="PROMOTED","evidence_linked","UNKNOWN_or_unverified")
A8: E001 | B8: AcmeRival | C8: SEG_MM | D8: features | E8: =LET(v,IFERROR(LOOKUP(2,1/((tblClaimCandidates[entity_id]=[@entity_id])*(tblClaimCandidates[field_key]=[@field_key])*(tblClaimCandidates[status_final]="PROMOTED")),tblClaimCandidates[value_text]),""),IF(v="","UNKNOWN",v)) | F8: =LET(cnt,COUNTIFS(tblClaimCandidates[entity_id],[@entity_id],tblClaimCandidates[field_key],[@field_key],tblClaimCandidates[status_final],"PROMOTED"),IF(cnt=0,NA(),SUMIFS(tblClaimCandidates[value_num],tblClaimCandidates[entity_id],[@entity_id],tblClaimCandidates[field_key],[@field_key],tblClaimCandidates[status_final],"PROMOTED"))) | G8: =IFERROR(XLOOKUP([@field_key],tblFieldDictionary[field_key],tblFieldDictionary[units]),"") | H8: =LET(cnt,COUNTIFS(tblClaimCandidates[entity_id],[@entity_id],tblClaimCandidates[field_key],[@field_key],tblClaimCandidates[status_final],"PROMOTED"),IF(cnt=0,NA(),AVERAGEIFS(tblClaimCandidates[confidence],tblClaimCandidates[entity_id],[@entity_id],tblClaimCandidates[field_key],[@field_key],tblClaimCandidates[status_final],"PROMOTED"))) | I8: =IFERROR(LOOKUP(2,1/((tblClaimCandidates[entity_id]=[@entity_id])*(tblClaimCandidates[field_key]=[@field_key])*(tblClaimCandidates[status_final]="PROMOTED")),tblClaimCandidates[evidence_id]),"") | J8: =IF([@evidence_id]="","",IFERROR(XLOOKUP([@evidence_id],tblEvidence[evidence_id],tblEvidence[url],""),"")) | K8: =IFERROR(LOOKUP(2,1/((tblClaimCandidates[entity_id]=[@entity_id])*(tblClaimCandidates[field_key]=[@field_key])*(tblClaimCandidates[status_final]="PROMOTED")),tblClaimCandidates[tier]),"") | L8: =IF([@value_text]="UNKNOWN","UNKNOWN","PROMOTED") | M8: =IF([@status]="PROMOTED",TODAY(),"") | N8: =IF([@status]="PROMOTED","evidence_linked","UNKNOWN_or_unverified")
A9: E001 | B9: AcmeRival | C9: SEG_MM | D9: funding_round | E9: =LET(v,IFERROR(LOOKUP(2,1/((tblClaimCandidates[entity_id]=[@entity_id])*(tblClaimCandidates[field_key]=[@field_key])*(tblClaimCandidates[status_final]="PROMOTED")),tblClaimCandidates[value_text]),""),IF(v="","UNKNOWN",v)) | F9: =LET(cnt,COUNTIFS(tblClaimCandidates[entity_id],[@entity_id],tblClaimCandidates[field_key],[@field_key],tblClaimCandidates[status_final],"PROMOTED"),IF(cnt=0,NA(),SUMIFS(tblClaimCandidates[value_num],tblClaimCandidates[entity_id],[@entity_id],tblClaimCandidates[field_key],[@field_key],tblClaimCandidates[status_final],"PROMOTED"))) | G9: =IFERROR(XLOOKUP([@field_key],tblFieldDictionary[field_key],tblFieldDictionary[units]),"") | H9: =LET(cnt,COUNTIFS(tblClaimCandidates[entity_id],[@entity_id],tblClaimCandidates[field_key],[@field_key],tblClaimCandidates[status_final],"PROMOTED"),IF(cnt=0,NA(),AVERAGEIFS(tblClaimCandidates[confidence],tblClaimCandidates[entity_id],[@entity_id],tblClaimCandidates[field_key],[@field_key],tblClaimCandidates[status_final],"PROMOTED"))) | I9: =IFERROR(LOOKUP(2,1/((tblClaimCandidates[entity_id]=[@entity_id])*(tblClaimCandidates[field_key]=[@field_key])*(tblClaimCandidates[status_final]="PROMOTED")),tblClaimCandidates[evidence_id]),"") | J9: =IF([@evidence_id]="","",IFERROR(XLOOKUP([@evidence_id],tblEvidence[evidence_id],tblEvidence[url],""),"")) | K9: =IFERROR(LOOKUP(2,1/((tblClaimCandidates[entity_id]=[@entity_id])*(tblClaimCandidates[field_key]=[@field_key])*(tblClaimCandidates[status_final]="PROMOTED")),tblClaimCandidates[tier]),"") | L9: =IF([@value_text]="UNKNOWN","UNKNOWN","PROMOTED") | M9: =IF([@status]="PROMOTED",TODAY(),"") | N9: =IF([@status]="PROMOTED","evidence_linked","UNKNOWN_or_unverified")
A10: E001 | B10: AcmeRival | C10: SEG_MM | D10: geo_coverage | E10: =LET(v,IFERROR(LOOKUP(2,1/((tblClaimCandidates[entity_id]=[@entity_id])*(tblClaimCandidates[field_key]=[@field_key])*(tblClaimCandidates[status_final]="PROMOTED")),tblClaimCandidates[value_text]),""),IF(v="","UNKNOWN",v)) | F10: =LET(cnt,COUNTIFS(tblClaimCandidates[entity_id],[@entity_id],tblClaimCandidates[field_key],[@field_key],tblClaimCandidates[status_final],"PROMOTED"),IF(cnt=0,NA(),SUMIFS(tblClaimCandidates[value_num],tblClaimCandidates[entity_id],[@entity_id],tblClaimCandidates[field_key],[@field_key],tblClaimCandidates[status_final],"PROMOTED"))) | G10: =IFERROR(XLOOKUP([@field_key],tblFieldDictionary[field_key],tblFieldDictionary[units]),"") | H10: =LET(cnt,COUNTIFS(tblClaimCandidates[entity_id],[@entity_id],tblClaimCandidates[field_key],[@field_key],tblClaimCandidates[status_final],"PROMOTED"),IF(cnt=0,NA(),AVERAGEIFS(tblClaimCandidates[confidence],tblClaimCandidates[entity_id],[@entity_id],tblClaimCandidates[field_key],[@field_key],tblClaimCandidates[status_final],"PROMOTED"))) | I10: =IFERROR(LOOKUP(2,1/((tblClaimCandidates[entity_id]=[@entity_id])*(tblClaimCandidates[field_key]=[@field_key])*(tblClaimCandidates[status_final]="PROMOTED")),tblClaimCandidates[evidence_id]),"") | J10: =IF([@evidence_id]="","",IFERROR(XLOOKUP([@evidence_id],tblEvidence[evidence_id],tblEvidence[url],""),"")) | K10: =IFERROR(LOOKUP(2,1/((tblClaimCandidates[entity_id]=[@entity_id])*(tblClaimCandidates[field_key]=[@field_key])*(tblClaimCandidates[status_final]="PROMOTED")),tblClaimCandidates[tier]),"") | L10: =IF([@value_text]="UNKNOWN","UNKNOWN","PROMOTED") | M10: =IF([@status]="PROMOTED",TODAY(),"") | N10: =IF([@status]="PROMOTED","evidence_linked","UNKNOWN_or_unverified")
A11: E001 | B11: AcmeRival | C11: SEG_MM | D11: practice_size_target | E11: =LET(v,IFERROR(LOOKUP(2,1/((tblClaimCandidates[entity_id]=[@entity_id])*(tblClaimCandidates[field_key]=[@field_key])*(tblClaimCandidates[status_final]="PROMOTED")),tblClaimCandidates[value_text]),""),IF(v="","UNKNOWN",v)) | F11: =LET(cnt,COUNTIFS(tblClaimCandidates[entity_id],[@entity_id],tblClaimCandidates[field_key],[@field_key],tblClaimCandidates[status_final],"PROMOTED"),IF(cnt=0,NA(),SUMIFS(tblClaimCandidates[value_num],tblClaimCandidates[entity_id],[@entity_id],tblClaimCandidates[field_key],[@field_key],tblClaimCandidates[status_final],"PROMOTED"))) | G11: =IFERROR(XLOOKUP([@field_key],tblFieldDictionary[field_key],tblFieldDictionary[units]),"") | H11: =LET(cnt,COUNTIFS(tblClaimCandidates[entity_id],[@entity_id],tblClaimCandidates[field_key],[@field_key],tblClaimCandidates[status_final],"PROMOTED"),IF(cnt=0,NA(),AVERAGEIFS(tblClaimCandidates[confidence],tblClaimCandidates[entity_id],[@entity_id],tblClaimCandidates[field_key],[@field_key],tblClaimCandidates[status_final],"PROMOTED"))) | I11: =IFERROR(LOOKUP(2,1/((tblClaimCandidates[entity_id]=[@entity_id])*(tblClaimCandidates[field_key]=[@field_key])*(tblClaimCandidates[status_final]="PROMOTED")),tblClaimCandidates[evidence_id]),"") | J11: =IF([@evidence_id]="","",IFERROR(XLOOKUP([@evidence_id],tblEvidence[evidence_id],tblEvidence[url],""),"")) | K11: =IFERROR(LOOKUP(2,1/((tblClaimCandidates[entity_id]=[@entity_id])*(tblClaimCandidates[field_key]=[@field_key])*(tblClaimCandidates[status_final]="PROMOTED")),tblClaimCandidates[tier]),"") | L11: =IF([@value_text]="UNKNOWN","UNKNOWN","PROMOTED") | M11: =IF([@status]="PROMOTED",TODAY(),"") | N11: =IF([@status]="PROMOTED","evidence_linked","UNKNOWN_or_unverified")
A12: E002 | B12: EnrollPro | C12: SEG_MM | D12: pricing_acv_mid_market | E12: =LET(v,IFERROR(LOOKUP(2,1/((tblClaimCandidates[entity_id]=[@entity_id])*(tblClaimCandidates[field_key]=[@field_key])*(tblClaimCandidates[status_final]="PROMOTED")),tblClaimCandidates[value_text]),""),IF(v="","UNKNOWN",v)) | F12: =LET(cnt,COUNTIFS(tblClaimCandidates[entity_id],[@entity_id],tblClaimCandidates[field_key],[@field_key],tblClaimCandidates[status_final],"PROMOTED"),IF(cnt=0,NA(),SUMIFS(tblClaimCandidates[value_num],tblClaimCandidates[entity_id],[@entity_id],tblClaimCandidates[field_key],[@field_key],tblClaimCandidates[status_final],"PROMOTED"))) | G12: =IFERROR(XLOOKUP([@field_key],tblFieldDictionary[field_key],tblFieldDictionary[units]),"") | H12: =LET(cnt,COUNTIFS(tblClaimCandidates[entity_id],[@entity_id],tblClaimCandidates[field_key],[@field_key],tblClaimCandidates[status_final],"PROMOTED"),IF(cnt=0,NA(),AVERAGEIFS(tblClaimCandidates[confidence],tblClaimCandidates[entity_id],[@entity_id],tblClaimCandidates[field_key],[@field_key],tblClaimCandidates[status_final],"PROMOTED"))) | I12: =IFERROR(LOOKUP(2,1/((tblClaimCandidates[entity_id]=[@entity_id])*(tblClaimCandidates[field_key]=[@field_key])*(tblClaimCandidates[status_final]="PROMOTED")),tblClaimCandidates[evidence_id]),"") | J12: =IF([@evidence_id]="","",IFERROR(XLOOKUP([@evidence_id],tblEvidence[evidence_id],tblEvidence[url],""),"")) | K12: =IFERROR(LOOKUP(2,1/((tblClaimCandidates[entity_id]=[@entity_id])*(tblClaimCandidates[field_key]=[@field_key])*(tblClaimCandidates[status_final]="PROMOTED")),tblClaimCandidates[tier]),"") | L12: =IF([@value_text]="UNKNOWN","UNKNOWN","PROMOTED") | M12: =IF([@status]="PROMOTED",TODAY(),"") | N12: =IF([@status]="PROMOTED","evidence_linked","UNKNOWN_or_unverified")
A13: E002 | B13: EnrollPro | C13: SEG_MM | D13: arr_estimate | E13: =LET(v,IFERROR(LOOKUP(2,1/((tblClaimCandidates[entity_id]=[@entity_id])*(tblClaimCandidates[field_key]=[@field_key])*(tblClaimCandidates[status_final]="PROMOTED")),tblClaimCandidates[value_text]),""),IF(v="","UNKNOWN",v)) | F13: =LET(cnt,COUNTIFS(tblClaimCandidates[entity_id],[@entity_id],tblClaimCandidates[field_key],[@field_key],tblClaimCandidates[status_final],"PROMOTED"),IF(cnt=0,NA(),SUMIFS(tblClaimCandidates[value_num],tblClaimCandidates[entity_id],[@entity_id],tblClaimCandidates[field_key],[@field_key],tblClaimCandidates[status_final],"PROMOTED"))) | G13: =IFERROR(XLOOKUP([@field_key],tblFieldDictionary[field_key],tblFieldDictionary[units]),"") | H13: =LET(cnt,COUNTIFS(tblClaimCandidates[entity_id],[@entity_id],tblClaimCandidates[field_key],[@field_key],tblClaimCandidates[status_final],"PROMOTED"),IF(cnt=0,NA(),AVERAGEIFS(tblClaimCandidates[confidence],tblClaimCandidates[entity_id],[@entity_id],tblClaimCandidates[field_key],[@field_key],tblClaimCandidates[status_final],"PROMOTED"))) | I13: =IFERROR(LOOKUP(2,1/((tblClaimCandidates[entity_id]=[@entity_id])*(tblClaimCandidates[field_key]=[@field_key])*(tblClaimCandidates[status_final]="PROMOTED")),tblClaimCandidates[evidence_id]),"") | J13: =IF([@evidence_id]="","",IFERROR(XLOOKUP([@evidence_id],tblEvidence[evidence_id],tblEvidence[url],""),"")) | K13: =IFERROR(LOOKUP(2,1/((tblClaimCandidates[entity_id]=[@entity_id])*(tblClaimCandidates[field_key]=[@field_key])*(tblClaimCandidates[status_final]="PROMOTED")),tblClaimCandidates[tier]),"") | L13: =IF([@value_text]="UNKNOWN","UNKNOWN","PROMOTED") | M13: =IF([@status]="PROMOTED",TODAY(),"") | N13: =IF([@status]="PROMOTED","evidence_linked","UNKNOWN_or_unverified")
A14: E002 | B14: EnrollPro | C14: SEG_MM | D14: contract_terms | E14: =LET(v,IFERROR(LOOKUP(2,1/((tblClaimCandidates[entity_id]=[@entity_id])*(tblClaimCandidates[field_key]=[@field_key])*(tblClaimCandidates[status_final]="PROMOTED")),tblClaimCandidates[value_text]),""),IF(v="","UNKNOWN",v)) | F14: =LET(cnt,COUNTIFS(tblClaimCandidates[entity_id],[@entity_id],tblClaimCandidates[field_key],[@field_key],tblClaimCandidates[status_final],"PROMOTED"),IF(cnt=0,NA(),SUMIFS(tblClaimCandidates[value_num],tblClaimCandidates[entity_id],[@entity_id],tblClaimCandidates[field_key],[@field_key],tblClaimCandidates[status_final],"PROMOTED"))) | G14: =IFERROR(XLOOKUP([@field_key],tblFieldDictionary[field_key],tblFieldDictionary[units]),"") | H14: =LET(cnt,COUNTIFS(tblClaimCandidates[entity_id],[@entity_id],tblClaimCandidates[field_key],[@field_key],tblClaimCandidates[status_final],"PROMOTED"),IF(cnt=0,NA(),AVERAGEIFS(tblClaimCandidates[confidence],tblClaimCandidates[entity_id],[@entity_id],tblClaimCandidates[field_key],[@field_key],tblClaimCandidates[status_final],"PROMOTED"))) | I14: =IFERROR(LOOKUP(2,1/((tblClaimCandidates[entity_id]=[@entity_id])*(tblClaimCandidates[field_key]=[@field_key])*(tblClaimCandidates[status_final]="PROMOTED")),tblClaimCandidates[evidence_id]),"") | J14: =IF([@evidence_id]="","",IFERROR(XLOOKUP([@evidence_id],tblEvidence[evidence_id],tblEvidence[url],""),"")) | K14: =IFERROR(LOOKUP(2,1/((tblClaimCandidates[entity_id]=[@entity_id])*(tblClaimCandidates[field_key]=[@field_key])*(tblClaimCandidates[status_final]="PROMOTED")),tblClaimCandidates[tier]),"") | L14: =IF([@value_text]="UNKNOWN","UNKNOWN","PROMOTED") | M14: =IF([@status]="PROMOTED",TODAY(),"") | N14: =IF([@status]="PROMOTED","evidence_linked","UNKNOWN_or_unverified")
A15: E002 | B15: EnrollPro | C15: SEG_MM | D15: features | E15: =LET(v,IFERROR(LOOKUP(2,1/((tblClaimCandidates[entity_id]=[@entity_id])*(tblClaimCandidates[field_key]=[@field_key])*(tblClaimCandidates[status_final]="PROMOTED")),tblClaimCandidates[value_text]),""),IF(v="","UNKNOWN",v)) | F15: =LET(cnt,COUNTIFS(tblClaimCandidates[entity_id],[@entity_id],tblClaimCandidates[field_key],[@field_key],tblClaimCandidates[status_final],"PROMOTED"),IF(cnt=0,NA(),SUMIFS(tblClaimCandidates[value_num],tblClaimCandidates[entity_id],[@entity_id],tblClaimCandidates[field_key],[@field_key],tblClaimCandidates[status_final],"PROMOTED"))) | G15: =IFERROR(XLOOKUP([@field_key],tblFieldDictionary[field_key],tblFieldDictionary[units]),"") | H15: =LET(cnt,COUNTIFS(tblClaimCandidates[entity_id],[@entity_id],tblClaimCandidates[field_key],[@field_key],tblClaimCandidates[status_final],"PROMOTED"),IF(cnt=0,NA(),AVERAGEIFS(tblClaimCandidates[confidence],tblClaimCandidates[entity_id],[@entity_id],tblClaimCandidates[field_key],[@field_key],tblClaimCandidates[status_final],"PROMOTED"))) | I15: =IFERROR(LOOKUP(2,1/((tblClaimCandidates[entity_id]=[@entity_id])*(tblClaimCandidates[field_key]=[@field_key])*(tblClaimCandidates[status_final]="PROMOTED")),tblClaimCandidates[evidence_id]),"") | J15: =IF([@evidence_id]="","",IFERROR(XLOOKUP([@evidence_id],tblEvidence[evidence_id],tblEvidence[url],""),"")) | K15: =IFERROR(LOOKUP(2,1/((tblClaimCandidates[entity_id]=[@entity_id])*(tblClaimCandidates[field_key]=[@field_key])*(tblClaimCandidates[status_final]="PROMOTED")),tblClaimCandidates[tier]),"") | L15: =IF([@value_text]="UNKNOWN","UNKNOWN","PROMOTED") | M15: =IF([@status]="PROMOTED",TODAY(),"") | N15: =IF([@status]="PROMOTED","evidence_linked","UNKNOWN_or_unverified")
A16: E002 | B16: EnrollPro | C16: SEG_MM | D16: funding_round | E16: =LET(v,IFERROR(LOOKUP(2,1/((tblClaimCandidates[entity_id]=[@entity_id])*(tblClaimCandidates[field_key]=[@field_key])*(tblClaimCandidates[status_final]="PROMOTED")),tblClaimCandidates[value_text]),""),IF(v="","UNKNOWN",v)) | F16: =LET(cnt,COUNTIFS(tblClaimCandidates[entity_id],[@entity_id],tblClaimCandidates[field_key],[@field_key],tblClaimCandidates[status_final],"PROMOTED"),IF(cnt=0,NA(),SUMIFS(tblClaimCandidates[value_num],tblClaimCandidates[entity_id],[@entity_id],tblClaimCandidates[field_key],[@field_key],tblClaimCandidates[status_final],"PROMOTED"))) | G16: =IFERROR(XLOOKUP([@field_key],tblFieldDictionary[field_key],tblFieldDictionary[units]),"") | H16: =LET(cnt,COUNTIFS(tblClaimCandidates[entity_id],[@entity_id],tblClaimCandidates[field_key],[@field_key],tblClaimCandidates[status_final],"PROMOTED"),IF(cnt=0,NA(),AVERAGEIFS(tblClaimCandidates[confidence],tblClaimCandidates[entity_id],[@entity_id],tblClaimCandidates[field_key],[@field_key],tblClaimCandidates[status_final],"PROMOTED"))) | I16: =IFERROR(LOOKUP(2,1/((tblClaimCandidates[entity_id]=[@entity_id])*(tblClaimCandidates[field_key]=[@field_key])*(tblClaimCandidates[status_final]="PROMOTED")),tblClaimCandidates[evidence_id]),"") | J16: =IF([@evidence_id]="","",IFERROR(XLOOKUP([@evidence_id],tblEvidence[evidence_id],tblEvidence[url],""),"")) | K16: =IFERROR(LOOKUP(2,1/((tblClaimCandidates[entity_id]=[@entity_id])*(tblClaimCandidates[field_key]=[@field_key])*(tblClaimCandidates[status_final]="PROMOTED")),tblClaimCandidates[tier]),"") | L16: =IF([@value_text]="UNKNOWN","UNKNOWN","PROMOTED") | M16: =IF([@status]="PROMOTED",TODAY(),"") | N16: =IF([@status]="PROMOTED","evidence_linked","UNKNOWN_or_unverified")
... A46: E006 | B46: MidMarketMedTech | C46: SEG_MM | D46: practice_size_target | E46: =LET(v,IFERROR(LOOKUP(2,1/((tblClaimCandidates[entity_id]=[@entity_id])*(tblClaimCandidates[field_key]=[@field_key])*(tblClaimCandidates[status_final]="PROMOTED")),tblClaimCandidates[value_text]),""),IF(v="","UNKNOWN",v)) | F46: =LET(cnt,COUNTIFS(tblClaimCandidates[entity_id],[@entity_id],tblClaimCandidates[field_key],[@field_key],tblClaimCandidates[status_final],"PROMOTED"),IF(cnt=0,NA(),SUMIFS(tblClaimCandidates[value_num],tblClaimCandidates[entity_id],[@entity_id],tblClaimCandidates[field_key],[@field_key],tblClaimCandidates[status_final],"PROMOTED"))) | G46: =IFERROR(XLOOKUP([@field_key],tblFieldDictionary[field_key],tblFieldDictionary[units]),"") | H46: =LET(cnt,COUNTIFS(tblClaimCandidates[entity_id],[@entity_id],tblClaimCandidates[field_key],[@field_key],tblClaimCandidates[status_final],"PROMOTED"),IF(cnt=0,NA(),AVERAGEIFS(tblClaimCandidates[confidence],tblClaimCandidates[entity_id],[@entity_id],tblClaimCandidates[field_key],[@field_key],tblClaimCandidates[status_final],"PROMOTED"))) | I46: =IFERROR(LOOKUP(2,1/((tblClaimCandidates[entity_id]=[@entity_id])*(tblClaimCandidates[field_key]=[@field_key])*(tblClaimCandidates[status_final]="PROMOTED")),tblClaimCandidates[evidence_id]),"") | J46: =IF([@evidence_id]="","",IFERROR(XLOOKUP([@evidence_id],tblEvidence[evidence_id],tblEvidence[url],""),"")) | K46: =IFERROR(LOOKUP(2,1/((tblClaimCandidates[entity_id]=[@entity_id])*(tblClaimCandidates[field_key]=[@field_key])*(tblClaimCandidates[status_final]="PROMOTED")),tblClaimCandidates[tier]),"") | L46: =IF([@value_text]="UNKNOWN","UNKNOWN","PROMOTED") | M46: =IF([@status]="PROMOTED",TODAY(),"") | N46: =IF([@status]="PROMOTED","evidence_linked","UNKNOWN_or_unverified")

Sheet Metrics
A1: Metrics (Derived; Formula-Driven)
A2: All figures are derived from Claims_Current (which must be evidence-backed). UNKNOWN propagates to Review Queue and fail-closed flags.
A4: Global Drivers
A5: Median ACV (USD/year) | B5: =IFERROR(MEDIAN(FILTER($G$8:$G$57,ISNUMBER($G$8:$G$57))),"") | D5: Evidence Freshness Threshold (days) | E5: =Config!$B$9 | G5: Min Coverage (fail-closed) | H5: =Config!$B$10
A7: entity_id | B7: canonical_name | C7: known_claims | D7: unknown_claims | E7: coverage_pct | F7: avg_conf | G7: acv_usd | H7: acv_band | I7: features_text | J7: feature_count | K7: segment_fit | L7: funding_present | M7: threat_score | N7: opportunity_score | O7: flags | P7: segment_id | Q7: vertical | R7: in_scope | AA7: competitors_in_scope
A8: =IF(Input!$A$7="","",Input!$A$7) | B8: =IFERROR(XLOOKUP([@entity_id],tblEntities[entity_id],tblEntities[canonical_name]),"") | C8: =IF([@entity_id]="","",COUNTIFS(tblClaimsCurrent[entity_id],[@entity_id],tblClaimsCurrent[status],"PROMOTED")) | D8: =IF([@entity_id]="","",COUNTIFS(tblClaimsCurrent[entity_id],[@entity_id],tblClaimsCurrent[status],"UNKNOWN")) | E8: =LET(t,[@known_claims]+[@unknown_claims],IF(t=0,NA(),[@known_claims]/t)) | F8: =LET(cnt,COUNTIFS(tblClaimsCurrent[entity_id],[@entity_id],tblClaimsCurrent[status],"PROMOTED"),IF(cnt=0,NA(),AVERAGEIFS(tblClaimsCurrent[confidence],tblClaimsCurrent[entity_id],[@entity_id],tblClaimsCurrent[status],"PROMOTED"))) | G8: =LET(cnt,COUNTIFS(tblClaimsCurrent[entity_id],[@entity_id],tblClaimsCurrent[field_key],"pricing_acv_mid_market",tblClaimsCurrent[status],"PROMOTED"),IF(cnt=0,NA(),SUMIFS(tblClaimsCurrent[value_num],tblClaimsCurrent[entity_id],[@entity_id],tblClaimsCurrent[field_key],"pricing_acv_mid_market",tblClaimsCurrent[status],"PROMOTED"))) | H8: =IF(OR(NOT(ISNUMBER([@acv_usd])),$B$5=""),"UNKNOWN",IF([@acv_usd]<=($B$5*0.85),"Low",IF([@acv_usd]>=($B$5*1.15),"High","Mid"))) | I8: =LET(v,IFERROR(LOOKUP(2,1/((tblClaimsCurrent[entity_id]=[@entity_id])*(tblClaimsCurrent[field_key]="features")*(tblClaimsCurrent[status]="PROMOTED")),tblClaimsCurrent[value_text]),"UNKNOWN"),IF(v="","UNKNOWN",v)) | J8: =IF(OR([@features_text]="UNKNOWN",[@features_text]=""),NA(),1+LEN([@features_text])-LEN(SUBSTITUTE([@features_text],";",""))) | K8: =IF([@segment_id]="",NA(),IF([@segment_id]="SEG_MM",1,0)) | L8: =IF([@entity_id]="","",IF(COUNTIFS(tblClaimsCurrent[entity_id],[@entity_id],tblClaimsCurrent[field_key],"funding_round",tblClaimsCurrent[status],"PROMOTED")>0,1,0)) | M8: =IF(OR([@in_scope]=FALSE,ISNA([@coverage_pct]),ISNA([@feature_count]),ISNA([@segment_fit]),[@acv_band]="UNKNOWN"),NA(),MIN(1,Config!$B$14*MIN(1,[@feature_count]/10)+Config!$B$15*IF([@acv_band]="Low",1,IF([@acv_band]="Mid",0.5,0))+Config!$B$16*[@segment_fit]+Config!$B$17*[@funding_present])) | N8: =IF(OR([@in_scope]=FALSE,ISNA([@coverage_pct]),ISNA([@feature_count]),ISNA([@segment_fit])),NA(),MIN(1,Config!$B$18*(1-MIN(1,[@feature_count]/10))+Config!$B$19*(1-[@segment_fit])+Config!$B$20*(1-[@coverage_pct]))) | O8: =IF([@in_scope]=FALSE,"OUT_OF_SCOPE",IF(ISNA([@coverage_pct]),"UNKNOWN",IF([@coverage_pct]<Config!$B$10,"FAIL_CLOSED_LOW_COVERAGE","OK"))) | P8: =IFERROR(XLOOKUP([@entity_id],tblEntities[entity_id],tblEntities[segment_id]),"") | Q8: =IFERROR(XLOOKUP([@entity_id],tblEntities[entity_id],tblEntities[vertical]),"") | R8: =AND([@segment_id]=Dashboard!$E$2,IF(Dashboard!$E$3="All",TRUE,[@vertical]=Dashboard!$E$3)) | AA8: =LET(seg,Dashboard!$E$2,vert,Dashboard!$E$3,n,FILTER(tblEntities[canonical_name],(tblEntities[segment_id]=seg)*IF(vert="All",1,(tblEntities[vertical]=vert))*(tblEntities[status]<>"ARCHIVED")),IFERROR(SORT(n),""))
A9: =IF(Input!$A$8="","",Input!$A$8) | B9: =IFERROR(XLOOKUP([@entity_id],tblEntities[entity_id],tblEntities[canonical_name]),"") | C9: =IF([@entity_id]="","",COUNTIFS(tblClaimsCurrent[entity_id],[@entity_id],tblClaimsCurrent[status],"PROMOTED")) | D9: =IF([@entity_id]="","",COUNTIFS(tblClaimsCurrent[entity_id],[@entity_id],tblClaimsCurrent[status],"UNKNOWN")) | E9: =LET(t,[@known_claims]+[@unknown_claims],IF(t=0,NA(),[@known_claims]/t)) | F9: =LET(cnt,COUNTIFS(tblClaimsCurrent[entity_id],[@entity_id],tblClaimsCurrent[status],"PROMOTED"),IF(cnt=0,NA(),AVERAGEIFS(tblClaimsCurrent[confidence],tblClaimsCurrent[entity_id],[@entity_id],tblClaimsCurrent[status],"PROMOTED"))) | G9: =LET(cnt,COUNTIFS(tblClaimsCurrent[entity_id],[@entity_id],tblClaimsCurrent[field_key],"pricing_acv_mid_market",tblClaimsCurrent[status],"PROMOTED"),IF(cnt=0,NA(),SUMIFS(tblClaimsCurrent[value_num],tblClaimsCurrent[entity_id],[@entity_id],tblClaimsCurrent[field_key],"pricing_acv_mid_market",tblClaimsCurrent[status],"PROMOTED"))) | H9: =IF(OR(NOT(ISNUMBER([@acv_usd])),$B$5=""),"UNKNOWN",IF([@acv_usd]<=($B$5*0.85),"Low",IF([@acv_usd]>=($B$5*1.15),"High","Mid"))) | I9: =LET(v,IFERROR(LOOKUP(2,1/((tblClaimsCurrent[entity_id]=[@entity_id])*(tblClaimsCurrent[field_key]="features")*(tblClaimsCurrent[status]="PROMOTED")),tblClaimsCurrent[value_text]),"UNKNOWN"),IF(v="","UNKNOWN",v)) | J9: =IF(OR([@features_text]="UNKNOWN",[@features_text]=""),NA(),1+LEN([@features_text])-LEN(SUBSTITUTE([@features_text],";",""))) | K9: =IF([@segment_id]="",NA(),IF([@segment_id]="SEG_MM",1,0)) | L9: =IF([@entity_id]="","",IF(COUNTIFS(tblClaimsCurrent[entity_id],[@entity_id],tblClaimsCurrent[field_key],"funding_round",tblClaimsCurrent[status],"PROMOTED")>0,1,0)) | M9: =IF(OR([@in_scope]=FALSE,ISNA([@coverage_pct]),ISNA([@feature_count]),ISNA([@segment_fit]),[@acv_band]="UNKNOWN"),NA(),MIN(1,Config!$B$14*MIN(1,[@feature_count]/10)+Config!$B$15*IF([@acv_band]="Low",1,IF([@acv_band]="Mid",0.5,0))+Config!$B$16*[@segment_fit]+Config!$B$17*[@funding_present])) | N9: =IF(OR([@in_scope]=FALSE,ISNA([@coverage_pct]),ISNA([@feature_count]),ISNA([@segment_fit])),NA(),MIN(1,Config!$B$18*(1-MIN(1,[@feature_count]/10))+Config!$B$19*(1-[@segment_fit])+Config!$B$20*(1-[@coverage_pct]))) | O9: =IF([@in_scope]=FALSE,"OUT_OF_SCOPE",IF(ISNA([@coverage_pct]),"UNKNOWN",IF([@coverage_pct]<Config!$B$10,"FAIL_CLOSED_LOW_COVERAGE","OK"))) | P9: =IFERROR(XLOOKUP([@entity_id],tblEntities[entity_id],tblEntities[segment_id]),"") | Q9: =IFERROR(XLOOKUP([@entity_id],tblEntities[entity_id],tblEntities[vertical]),"") | R9: =AND([@segment_id]=Dashboard!$E$2,IF(Dashboard!$E$3="All",TRUE,[@vertical]=Dashboard!$E$3))
A10: =IF(Input!$A$9="","",Input!$A$9) | B10: =IFERROR(XLOOKUP([@entity_id],tblEntities[entity_id],tblEntities[canonical_name]),"") | C10: =IF([@entity_id]="","",COUNTIFS(tblClaimsCurrent[entity_id],[@entity_id],tblClaimsCurrent[status],"PROMOTED")) | D10: =IF([@entity_id]="","",COUNTIFS(tblClaimsCurrent[entity_id],[@entity_id],tblClaimsCurrent[status],"UNKNOWN")) | E10: =LET(t,[@known_claims]+[@unknown_claims],IF(t=0,NA(),[@known_claims]/t)) | F10: =LET(cnt,COUNTIFS(tblClaimsCurrent[entity_id],[@entity_id],tblClaimsCurrent[status],"PROMOTED"),IF(cnt=0,NA(),AVERAGEIFS(tblClaimsCurrent[confidence],tblClaimsCurrent[entity_id],[@entity_id],tblClaimsCurrent[status],"PROMOTED"))) | G10: =LET(cnt,COUNTIFS(tblClaimsCurrent[entity_id],[@entity_id],tblClaimsCurrent[field_key],"pricing_acv_mid_market",tblClaimsCurrent[status],"PROMOTED"),IF(cnt=0,NA(),SUMIFS(tblClaimsCurrent[value_num],tblClaimsCurrent[entity_id],[@entity_id],tblClaimsCurrent[field_key],"pricing_acv_mid_market",tblClaimsCurrent[status],"PROMOTED"))) | H10: =IF(OR(NOT(ISNUMBER([@acv_usd])),$B$5=""),"UNKNOWN",IF([@acv_usd]<=($B$5*0.85),"Low",IF([@acv_usd]>=($B$5*1.15),"High","Mid"))) | I10: =LET(v,IFERROR(LOOKUP(2,1/((tblClaimsCurrent[entity_id]=[@entity_id])*(tblClaimsCurrent[field_key]="features")*(tblClaimsCurrent[status]="PROMOTED")),tblClaimsCurrent[value_text]),"UNKNOWN"),IF(v="","UNKNOWN",v)) | J10: =IF(OR([@features_text]="UNKNOWN",[@features_text]=""),NA(),1+LEN([@features_text])-LEN(SUBSTITUTE([@features_text],";",""))) | K10: =IF([@segment_id]="",NA(),IF([@segment_id]="SEG_MM",1,0)) | L10: =IF([@entity_id]="","",IF(COUNTIFS(tblClaimsCurrent[entity_id],[@entity_id],tblClaimsCurrent[field_key],"funding_round",tblClaimsCurrent[status],"PROMOTED")>0,1,0)) | M10: =IF(OR([@in_scope]=FALSE,ISNA([@coverage_pct]),ISNA([@feature_count]),ISNA([@segment_fit]),[@acv_band]="UNKNOWN"),NA(),MIN(1,Config!$B$14*MIN(1,[@feature_count]/10)+Config!$B$15*IF([@acv_band]="Low",1,IF([@acv_band]="Mid",0.5,0))+Config!$B$16*[@segment_fit]+Config!$B$17*[@funding_present])) | N10: =IF(OR([@in_scope]=FALSE,ISNA([@coverage_pct]),ISNA([@feature_count]),ISNA([@segment_fit])),NA(),MIN(1,Config!$B$18*(1-MIN(1,[@feature_count]/10))+Config!$B$19*(1-[@segment_fit])+Config!$B$20*(1-[@coverage_pct]))) | O10: =IF([@in_scope]=FALSE,"OUT_OF_SCOPE",IF(ISNA([@coverage_pct]),"UNKNOWN",IF([@coverage_pct]<Config!$B$10,"FAIL_CLOSED_LOW_COVERAGE","OK"))) | P10: =IFERROR(XLOOKUP([@entity_id],tblEntities[entity_id],tblEntities[segment_id]),"") | Q10: =IFERROR(XLOOKUP([@entity_id],tblEntities[entity_id],tblEntities[vertical]),"") | R10: =AND([@segment_id]=Dashboard!$E$2,IF(Dashboard!$E$3="All",TRUE,[@vertical]=Dashboard!$E$3))
A11: =IF(Input!$A$10="","",Input!$A$10) | B11: =IFERROR(XLOOKUP([@entity_id],tblEntities[entity_id],tblEntities[canonical_name]),"") | C11: =IF([@entity_id]="","",COUNTIFS(tblClaimsCurrent[entity_id],[@entity_id],tblClaimsCurrent[status],"PROMOTED")) | D11: =IF([@entity_id]="","",COUNTIFS(tblClaimsCurrent[entity_id],[@entity_id],tblClaimsCurrent[status],"UNKNOWN")) | E11: =LET(t,[@known_claims]+[@unknown_claims],IF(t=0,NA(),[@known_claims]/t)) | F11: =LET(cnt,COUNTIFS(tblClaimsCurrent[entity_id],[@entity_id],tblClaimsCurrent[status],"PROMOTED"),IF(cnt=0,NA(),AVERAGEIFS(tblClaimsCurrent[confidence],tblClaimsCurrent[entity_id],[@entity_id],tblClaimsCurrent[status],"PROMOTED"))) | G11: =LET(cnt,COUNTIFS(tblClaimsCurrent[entity_id],[@entity_id],tblClaimsCurrent[field_key],"pricing_acv_mid_market",tblClaimsCurrent[status],"PROMOTED"),IF(cnt=0,NA(),SUMIFS(tblClaimsCurrent[value_num],tblClaimsCurrent[entity_id],[@entity_id],tblClaimsCurrent[field_key],"pricing_acv_mid_market",tblClaimsCurrent[status],"PROMOTED"))) | H11: =IF(OR(NOT(ISNUMBER([@acv_usd])),$B$5=""),"UNKNOWN",IF([@acv_usd]<=($B$5*0.85),"Low",IF([@acv_usd]>=($B$5*1.15),"High","Mid"))) | I11: =LET(v,IFERROR(LOOKUP(2,1/((tblClaimsCurrent[entity_id]=[@entity_id])*(tblClaimsCurrent[field_key]="features")*(tblClaimsCurrent[status]="PROMOTED")),tblClaimsCurrent[value_text]),"UNKNOWN"),IF(v="","UNKNOWN",v)) | J11: =IF(OR([@features_text]="UNKNOWN",[@features_text]=""),NA(),1+LEN([@features_text])-LEN(SUBSTITUTE([@features_text],";",""))) | K11: =IF([@segment_id]="",NA(),IF([@segment_id]="SEG_MM",1,0)) | L11: =IF([@entity_id]="","",IF(COUNTIFS(tblClaimsCurrent[entity_id],[@entity_id],tblClaimsCurrent[field_key],"funding_round",tblClaimsCurrent[status],"PROMOTED")>0,1,0)) | M11: =IF(OR([@in_scope]=FALSE,ISNA([@coverage_pct]),ISNA([@feature_count]),ISNA([@segment_fit]),[@acv_band]="UNKNOWN"),NA(),MIN(1,Config!$B$14*MIN(1,[@feature_count]/10)+Config!$B$15*IF([@acv_band]="Low",1,IF([@acv_band]="Mid",0.5,0))+Config!$B$16*[@segment_fit]+Config!$B$17*[@funding_present])) | N11: =IF(OR([@in_scope]=FALSE,ISNA([@coverage_pct]),ISNA([@feature_count]),ISNA([@segment_fit])),NA(),MIN(1,Config!$B$18*(1-MIN(1,[@feature_count]/10))+Config!$B$19*(1-[@segment_fit])+Config!$B$20*(1-[@coverage_pct]))) | O11: =IF([@in_scope]=FALSE,"OUT_OF_SCOPE",IF(ISNA([@coverage_pct]),"UNKNOWN",IF([@coverage_pct]<Config!$B$10,"FAIL_CLOSED_LOW_COVERAGE","OK"))) | P11: =IFERROR(XLOOKUP([@entity_id],tblEntities[entity_id],tblEntities[segment_id]),"") | Q11: =IFERROR(XLOOKUP([@entity_id],tblEntities[entity_id],tblEntities[vertical]),"") | R11: =AND([@segment_id]=Dashboard!$E$2,IF(Dashboard!$E$3="All",TRUE,[@vertical]=Dashboard!$E$3))
